{
 "cells": [
  {
   "cell_type": "code",
   "execution_count": 1,
   "id": "8a4e5179-0408-41f0-83e9-42db127a1811",
   "metadata": {},
   "outputs": [],
   "source": [
    "from tensorflow.keras.models import load_model\n",
    "model = load_model(\"rice_classifier.h5\")  # replace with your actual model file name\n"
   ]
  },
  {
   "cell_type": "code",
   "execution_count": 2,
   "id": "2b0ba509-bb18-49af-bcdf-c4d0421772f8",
   "metadata": {},
   "outputs": [
    {
     "ename": "NameError",
     "evalue": "name 'val_generator' is not defined",
     "output_type": "error",
     "traceback": [
      "\u001b[1;31m---------------------------------------------------------------------------\u001b[0m",
      "\u001b[1;31mNameError\u001b[0m                                 Traceback (most recent call last)",
      "Cell \u001b[1;32mIn[2], line 1\u001b[0m\n\u001b[1;32m----> 1\u001b[0m val_loss, val_acc \u001b[38;5;241m=\u001b[39m model\u001b[38;5;241m.\u001b[39mevaluate(\u001b[43mval_generator\u001b[49m)\n\u001b[0;32m      2\u001b[0m \u001b[38;5;28mprint\u001b[39m(\u001b[38;5;124mf\u001b[39m\u001b[38;5;124m\"\u001b[39m\u001b[38;5;124mValidation Accuracy: \u001b[39m\u001b[38;5;132;01m{\u001b[39;00mval_acc\u001b[38;5;241m*\u001b[39m\u001b[38;5;241m100\u001b[39m\u001b[38;5;132;01m:\u001b[39;00m\u001b[38;5;124m.2f\u001b[39m\u001b[38;5;132;01m}\u001b[39;00m\u001b[38;5;124m%\u001b[39m\u001b[38;5;124m\"\u001b[39m)\n\u001b[0;32m      3\u001b[0m \u001b[38;5;28mprint\u001b[39m(\u001b[38;5;124mf\u001b[39m\u001b[38;5;124m\"\u001b[39m\u001b[38;5;124mValidation Loss: \u001b[39m\u001b[38;5;132;01m{\u001b[39;00mval_loss\u001b[38;5;132;01m:\u001b[39;00m\u001b[38;5;124m.4f\u001b[39m\u001b[38;5;132;01m}\u001b[39;00m\u001b[38;5;124m\"\u001b[39m)\n",
      "\u001b[1;31mNameError\u001b[0m: name 'val_generator' is not defined"
     ]
    }
   ],
   "source": [
    "val_loss, val_acc = model.evaluate(val_generator)\n",
    "print(f\"Validation Accuracy: {val_acc*100:.2f}%\")\n",
    "print(f\"Validation Loss: {val_loss:.4f}\")\n"
   ]
  },
  {
   "cell_type": "code",
   "execution_count": null,
   "id": "2a13c43a-64fc-410b-9a3f-a1599d8e002a",
   "metadata": {},
   "outputs": [],
   "source": [
    "import matplotlib.pyplot as plt\n",
    "\n",
    "# Accuracy\n",
    "plt.plot(history.history['accuracy'], label='Train Accuracy')\n",
    "plt.plot(history.history['val_accuracy'], label='Validation Accuracy')\n",
    "plt.title('Accuracy over Epochs')\n",
    "plt.xlabel('Epoch')\n",
    "plt.ylabel('Accuracy')\n",
    "plt.legend()\n",
    "plt.show()\n",
    "\n",
    "# Loss\n",
    "plt.plot(history.history['loss'], label='Train Loss')\n",
    "plt.plot(history.history['val_loss'], label='Validation Loss')\n",
    "plt.title('Loss over Epochs')\n",
    "plt.xlabel('Epoch')\n",
    "plt.ylabel('Loss')\n",
    "plt.legend()\n",
    "plt.show()\n"
   ]
  },
  {
   "cell_type": "code",
   "execution_count": 3,
   "id": "e9bfbc16-ba6d-4324-9438-29645e66c9c4",
   "metadata": {},
   "outputs": [
    {
     "ename": "FileNotFoundError",
     "evalue": "[WinError 3] The system cannot find the path specified: 'dataset/validation'",
     "output_type": "error",
     "traceback": [
      "\u001b[1;31m---------------------------------------------------------------------------\u001b[0m",
      "\u001b[1;31mFileNotFoundError\u001b[0m                         Traceback (most recent call last)",
      "Cell \u001b[1;32mIn[3], line 6\u001b[0m\n\u001b[0;32m      3\u001b[0m \u001b[38;5;66;03m# Define the validation data generator (same settings as before)\u001b[39;00m\n\u001b[0;32m      4\u001b[0m val_datagen \u001b[38;5;241m=\u001b[39m ImageDataGenerator(rescale\u001b[38;5;241m=\u001b[39m\u001b[38;5;241m1.\u001b[39m\u001b[38;5;241m/\u001b[39m\u001b[38;5;241m255\u001b[39m)\n\u001b[1;32m----> 6\u001b[0m val_generator \u001b[38;5;241m=\u001b[39m \u001b[43mval_datagen\u001b[49m\u001b[38;5;241;43m.\u001b[39;49m\u001b[43mflow_from_directory\u001b[49m\u001b[43m(\u001b[49m\n\u001b[0;32m      7\u001b[0m \u001b[43m    \u001b[49m\u001b[38;5;124;43m\"\u001b[39;49m\u001b[38;5;124;43mdataset/validation\u001b[39;49m\u001b[38;5;124;43m\"\u001b[39;49m\u001b[43m,\u001b[49m\u001b[43m       \u001b[49m\u001b[38;5;66;43;03m# or your correct path\u001b[39;49;00m\n\u001b[0;32m      8\u001b[0m \u001b[43m    \u001b[49m\u001b[43mtarget_size\u001b[49m\u001b[38;5;241;43m=\u001b[39;49m\u001b[43m(\u001b[49m\u001b[38;5;241;43m224\u001b[39;49m\u001b[43m,\u001b[49m\u001b[43m \u001b[49m\u001b[38;5;241;43m224\u001b[39;49m\u001b[43m)\u001b[49m\u001b[43m,\u001b[49m\u001b[43m     \u001b[49m\u001b[38;5;66;43;03m# or the size used in training\u001b[39;49;00m\n\u001b[0;32m      9\u001b[0m \u001b[43m    \u001b[49m\u001b[43mbatch_size\u001b[49m\u001b[38;5;241;43m=\u001b[39;49m\u001b[38;5;241;43m32\u001b[39;49m\u001b[43m,\u001b[49m\n\u001b[0;32m     10\u001b[0m \u001b[43m    \u001b[49m\u001b[43mclass_mode\u001b[49m\u001b[38;5;241;43m=\u001b[39;49m\u001b[38;5;124;43m'\u001b[39;49m\u001b[38;5;124;43mcategorical\u001b[39;49m\u001b[38;5;124;43m'\u001b[39;49m\u001b[43m,\u001b[49m\n\u001b[0;32m     11\u001b[0m \u001b[43m    \u001b[49m\u001b[43mshuffle\u001b[49m\u001b[38;5;241;43m=\u001b[39;49m\u001b[38;5;28;43;01mFalse\u001b[39;49;00m\n\u001b[0;32m     12\u001b[0m \u001b[43m)\u001b[49m\n",
      "File \u001b[1;32m~\\.conda\\envs\\tf_env\\lib\\site-packages\\keras\\preprocessing\\image.py:1650\u001b[0m, in \u001b[0;36mImageDataGenerator.flow_from_directory\u001b[1;34m(self, directory, target_size, color_mode, classes, class_mode, batch_size, shuffle, seed, save_to_dir, save_prefix, save_format, follow_links, subset, interpolation, keep_aspect_ratio)\u001b[0m\n\u001b[0;32m   1564\u001b[0m \u001b[38;5;28;01mdef\u001b[39;00m \u001b[38;5;21mflow_from_directory\u001b[39m(\n\u001b[0;32m   1565\u001b[0m     \u001b[38;5;28mself\u001b[39m,\n\u001b[0;32m   1566\u001b[0m     directory,\n\u001b[1;32m   (...)\u001b[0m\n\u001b[0;32m   1580\u001b[0m     keep_aspect_ratio\u001b[38;5;241m=\u001b[39m\u001b[38;5;28;01mFalse\u001b[39;00m,\n\u001b[0;32m   1581\u001b[0m ):\n\u001b[0;32m   1582\u001b[0m \u001b[38;5;250m    \u001b[39m\u001b[38;5;124;03m\"\"\"Takes the path to a directory & generates batches of augmented data.\u001b[39;00m\n\u001b[0;32m   1583\u001b[0m \n\u001b[0;32m   1584\u001b[0m \u001b[38;5;124;03m    Args:\u001b[39;00m\n\u001b[1;32m   (...)\u001b[0m\n\u001b[0;32m   1648\u001b[0m \u001b[38;5;124;03m            and `y` is a numpy array of corresponding labels.\u001b[39;00m\n\u001b[0;32m   1649\u001b[0m \u001b[38;5;124;03m    \"\"\"\u001b[39;00m\n\u001b[1;32m-> 1650\u001b[0m     \u001b[38;5;28;01mreturn\u001b[39;00m \u001b[43mDirectoryIterator\u001b[49m\u001b[43m(\u001b[49m\n\u001b[0;32m   1651\u001b[0m \u001b[43m        \u001b[49m\u001b[43mdirectory\u001b[49m\u001b[43m,\u001b[49m\n\u001b[0;32m   1652\u001b[0m \u001b[43m        \u001b[49m\u001b[38;5;28;43mself\u001b[39;49m\u001b[43m,\u001b[49m\n\u001b[0;32m   1653\u001b[0m \u001b[43m        \u001b[49m\u001b[43mtarget_size\u001b[49m\u001b[38;5;241;43m=\u001b[39;49m\u001b[43mtarget_size\u001b[49m\u001b[43m,\u001b[49m\n\u001b[0;32m   1654\u001b[0m \u001b[43m        \u001b[49m\u001b[43mcolor_mode\u001b[49m\u001b[38;5;241;43m=\u001b[39;49m\u001b[43mcolor_mode\u001b[49m\u001b[43m,\u001b[49m\n\u001b[0;32m   1655\u001b[0m \u001b[43m        \u001b[49m\u001b[43mkeep_aspect_ratio\u001b[49m\u001b[38;5;241;43m=\u001b[39;49m\u001b[43mkeep_aspect_ratio\u001b[49m\u001b[43m,\u001b[49m\n\u001b[0;32m   1656\u001b[0m \u001b[43m        \u001b[49m\u001b[43mclasses\u001b[49m\u001b[38;5;241;43m=\u001b[39;49m\u001b[43mclasses\u001b[49m\u001b[43m,\u001b[49m\n\u001b[0;32m   1657\u001b[0m \u001b[43m        \u001b[49m\u001b[43mclass_mode\u001b[49m\u001b[38;5;241;43m=\u001b[39;49m\u001b[43mclass_mode\u001b[49m\u001b[43m,\u001b[49m\n\u001b[0;32m   1658\u001b[0m \u001b[43m        \u001b[49m\u001b[43mdata_format\u001b[49m\u001b[38;5;241;43m=\u001b[39;49m\u001b[38;5;28;43mself\u001b[39;49m\u001b[38;5;241;43m.\u001b[39;49m\u001b[43mdata_format\u001b[49m\u001b[43m,\u001b[49m\n\u001b[0;32m   1659\u001b[0m \u001b[43m        \u001b[49m\u001b[43mbatch_size\u001b[49m\u001b[38;5;241;43m=\u001b[39;49m\u001b[43mbatch_size\u001b[49m\u001b[43m,\u001b[49m\n\u001b[0;32m   1660\u001b[0m \u001b[43m        \u001b[49m\u001b[43mshuffle\u001b[49m\u001b[38;5;241;43m=\u001b[39;49m\u001b[43mshuffle\u001b[49m\u001b[43m,\u001b[49m\n\u001b[0;32m   1661\u001b[0m \u001b[43m        \u001b[49m\u001b[43mseed\u001b[49m\u001b[38;5;241;43m=\u001b[39;49m\u001b[43mseed\u001b[49m\u001b[43m,\u001b[49m\n\u001b[0;32m   1662\u001b[0m \u001b[43m        \u001b[49m\u001b[43msave_to_dir\u001b[49m\u001b[38;5;241;43m=\u001b[39;49m\u001b[43msave_to_dir\u001b[49m\u001b[43m,\u001b[49m\n\u001b[0;32m   1663\u001b[0m \u001b[43m        \u001b[49m\u001b[43msave_prefix\u001b[49m\u001b[38;5;241;43m=\u001b[39;49m\u001b[43msave_prefix\u001b[49m\u001b[43m,\u001b[49m\n\u001b[0;32m   1664\u001b[0m \u001b[43m        \u001b[49m\u001b[43msave_format\u001b[49m\u001b[38;5;241;43m=\u001b[39;49m\u001b[43msave_format\u001b[49m\u001b[43m,\u001b[49m\n\u001b[0;32m   1665\u001b[0m \u001b[43m        \u001b[49m\u001b[43mfollow_links\u001b[49m\u001b[38;5;241;43m=\u001b[39;49m\u001b[43mfollow_links\u001b[49m\u001b[43m,\u001b[49m\n\u001b[0;32m   1666\u001b[0m \u001b[43m        \u001b[49m\u001b[43msubset\u001b[49m\u001b[38;5;241;43m=\u001b[39;49m\u001b[43msubset\u001b[49m\u001b[43m,\u001b[49m\n\u001b[0;32m   1667\u001b[0m \u001b[43m        \u001b[49m\u001b[43minterpolation\u001b[49m\u001b[38;5;241;43m=\u001b[39;49m\u001b[43minterpolation\u001b[49m\u001b[43m,\u001b[49m\n\u001b[0;32m   1668\u001b[0m \u001b[43m        \u001b[49m\u001b[43mdtype\u001b[49m\u001b[38;5;241;43m=\u001b[39;49m\u001b[38;5;28;43mself\u001b[39;49m\u001b[38;5;241;43m.\u001b[39;49m\u001b[43mdtype\u001b[49m\u001b[43m,\u001b[49m\n\u001b[0;32m   1669\u001b[0m \u001b[43m    \u001b[49m\u001b[43m)\u001b[49m\n",
      "File \u001b[1;32m~\\.conda\\envs\\tf_env\\lib\\site-packages\\keras\\preprocessing\\image.py:563\u001b[0m, in \u001b[0;36mDirectoryIterator.__init__\u001b[1;34m(self, directory, image_data_generator, target_size, color_mode, classes, class_mode, batch_size, shuffle, seed, data_format, save_to_dir, save_prefix, save_format, follow_links, subset, interpolation, keep_aspect_ratio, dtype)\u001b[0m\n\u001b[0;32m    561\u001b[0m \u001b[38;5;28;01mif\u001b[39;00m \u001b[38;5;129;01mnot\u001b[39;00m classes:\n\u001b[0;32m    562\u001b[0m     classes \u001b[38;5;241m=\u001b[39m []\n\u001b[1;32m--> 563\u001b[0m     \u001b[38;5;28;01mfor\u001b[39;00m subdir \u001b[38;5;129;01min\u001b[39;00m \u001b[38;5;28msorted\u001b[39m(\u001b[43mos\u001b[49m\u001b[38;5;241;43m.\u001b[39;49m\u001b[43mlistdir\u001b[49m\u001b[43m(\u001b[49m\u001b[43mdirectory\u001b[49m\u001b[43m)\u001b[49m):\n\u001b[0;32m    564\u001b[0m         \u001b[38;5;28;01mif\u001b[39;00m os\u001b[38;5;241m.\u001b[39mpath\u001b[38;5;241m.\u001b[39misdir(os\u001b[38;5;241m.\u001b[39mpath\u001b[38;5;241m.\u001b[39mjoin(directory, subdir)):\n\u001b[0;32m    565\u001b[0m             classes\u001b[38;5;241m.\u001b[39mappend(subdir)\n",
      "\u001b[1;31mFileNotFoundError\u001b[0m: [WinError 3] The system cannot find the path specified: 'dataset/validation'"
     ]
    }
   ],
   "source": [
    "from tensorflow.keras.preprocessing.image import ImageDataGenerator\n",
    "\n",
    "# Define the validation data generator (same settings as before)\n",
    "val_datagen = ImageDataGenerator(rescale=1./255)\n",
    "\n",
    "val_generator = val_datagen.flow_from_directory(\n",
    "    \"dataset/validation\",       # or your correct path\n",
    "    target_size=(224, 224),     # or the size used in training\n",
    "    batch_size=32,\n",
    "    class_mode='categorical',\n",
    "    shuffle=False\n",
    ")\n"
   ]
  },
  {
   "cell_type": "code",
   "execution_count": 4,
   "id": "655aecfa-2cb7-4f23-917d-9f4831f3ff52",
   "metadata": {},
   "outputs": [
    {
     "name": "stdout",
     "output_type": "stream",
     "text": [
      ".\\.ipynb_checkpoints\n"
     ]
    }
   ],
   "source": [
    "import os\n",
    "for root, dirs, files in os.walk(\".\", topdown=True):\n",
    "    for name in dirs:\n",
    "        print(os.path.join(root, name))\n"
   ]
  },
  {
   "cell_type": "code",
   "execution_count": 5,
   "id": "5f3f94b9-6c1f-499d-b975-1cb0a91bedde",
   "metadata": {},
   "outputs": [
    {
     "name": "stdout",
     "output_type": "stream",
     "text": [
      "..\\.ipynb_checkpoints\n",
      "..\\anaconda_projects\n",
      "..\\app\n",
      "..\\data\n",
      "..\\docs\n",
      "..\\notebooks\n",
      "..\\saved_model\n",
      "..\\venv\n",
      "..\\anaconda_projects\\db\n",
      "..\\data\\Rice_Image_Dataset\n",
      "..\\data\\Rice_Image_Dataset_split\n",
      "..\\data\\Rice_Image_Dataset\\Arborio\n",
      "..\\data\\Rice_Image_Dataset\\Basmati\n",
      "..\\data\\Rice_Image_Dataset\\Ipsala\n",
      "..\\data\\Rice_Image_Dataset\\Jasmine\n",
      "..\\data\\Rice_Image_Dataset\\Karacadag\n",
      "..\\data\\Rice_Image_Dataset_split\\train\n",
      "..\\data\\Rice_Image_Dataset_split\\validation\n",
      "..\\data\\Rice_Image_Dataset_split\\train\\Arborio\n",
      "..\\data\\Rice_Image_Dataset_split\\train\\Basmati\n",
      "..\\data\\Rice_Image_Dataset_split\\train\\Ipsala\n",
      "..\\data\\Rice_Image_Dataset_split\\train\\Jasmine\n",
      "..\\data\\Rice_Image_Dataset_split\\train\\Karacadag\n",
      "..\\data\\Rice_Image_Dataset_split\\validation\\Arborio\n",
      "..\\data\\Rice_Image_Dataset_split\\validation\\Basmati\n",
      "..\\data\\Rice_Image_Dataset_split\\validation\\Ipsala\n",
      "..\\data\\Rice_Image_Dataset_split\\validation\\Jasmine\n",
      "..\\data\\Rice_Image_Dataset_split\\validation\\Karacadag\n",
      "..\\notebooks\\.ipynb_checkpoints\n",
      "..\\venv\\Include\n",
      "..\\venv\\Lib\n",
      "..\\venv\\Scripts\n",
      "..\\venv\\Lib\\site-packages\n",
      "..\\venv\\Lib\\site-packages\\pip\n",
      "..\\venv\\Lib\\site-packages\\pip-23.0.1.dist-info\n",
      "..\\venv\\Lib\\site-packages\\pkg_resources\n",
      "..\\venv\\Lib\\site-packages\\setuptools\n",
      "..\\venv\\Lib\\site-packages\\setuptools-56.0.0.dist-info\n",
      "..\\venv\\Lib\\site-packages\\_distutils_hack\n",
      "..\\venv\\Lib\\site-packages\\pip\\_internal\n",
      "..\\venv\\Lib\\site-packages\\pip\\_vendor\n",
      "..\\venv\\Lib\\site-packages\\pip\\__pycache__\n",
      "..\\venv\\Lib\\site-packages\\pip\\_internal\\cli\n",
      "..\\venv\\Lib\\site-packages\\pip\\_internal\\commands\n",
      "..\\venv\\Lib\\site-packages\\pip\\_internal\\distributions\n",
      "..\\venv\\Lib\\site-packages\\pip\\_internal\\index\n",
      "..\\venv\\Lib\\site-packages\\pip\\_internal\\locations\n",
      "..\\venv\\Lib\\site-packages\\pip\\_internal\\metadata\n",
      "..\\venv\\Lib\\site-packages\\pip\\_internal\\models\n",
      "..\\venv\\Lib\\site-packages\\pip\\_internal\\network\n",
      "..\\venv\\Lib\\site-packages\\pip\\_internal\\operations\n",
      "..\\venv\\Lib\\site-packages\\pip\\_internal\\req\n",
      "..\\venv\\Lib\\site-packages\\pip\\_internal\\resolution\n",
      "..\\venv\\Lib\\site-packages\\pip\\_internal\\utils\n",
      "..\\venv\\Lib\\site-packages\\pip\\_internal\\vcs\n",
      "..\\venv\\Lib\\site-packages\\pip\\_internal\\__pycache__\n",
      "..\\venv\\Lib\\site-packages\\pip\\_internal\\cli\\__pycache__\n",
      "..\\venv\\Lib\\site-packages\\pip\\_internal\\commands\\__pycache__\n",
      "..\\venv\\Lib\\site-packages\\pip\\_internal\\distributions\\__pycache__\n",
      "..\\venv\\Lib\\site-packages\\pip\\_internal\\index\\__pycache__\n",
      "..\\venv\\Lib\\site-packages\\pip\\_internal\\locations\\__pycache__\n",
      "..\\venv\\Lib\\site-packages\\pip\\_internal\\metadata\\importlib\n",
      "..\\venv\\Lib\\site-packages\\pip\\_internal\\metadata\\__pycache__\n",
      "..\\venv\\Lib\\site-packages\\pip\\_internal\\metadata\\importlib\\__pycache__\n",
      "..\\venv\\Lib\\site-packages\\pip\\_internal\\models\\__pycache__\n",
      "..\\venv\\Lib\\site-packages\\pip\\_internal\\network\\__pycache__\n",
      "..\\venv\\Lib\\site-packages\\pip\\_internal\\operations\\build\n",
      "..\\venv\\Lib\\site-packages\\pip\\_internal\\operations\\install\n",
      "..\\venv\\Lib\\site-packages\\pip\\_internal\\operations\\__pycache__\n",
      "..\\venv\\Lib\\site-packages\\pip\\_internal\\operations\\build\\__pycache__\n",
      "..\\venv\\Lib\\site-packages\\pip\\_internal\\operations\\install\\__pycache__\n",
      "..\\venv\\Lib\\site-packages\\pip\\_internal\\req\\__pycache__\n",
      "..\\venv\\Lib\\site-packages\\pip\\_internal\\resolution\\legacy\n",
      "..\\venv\\Lib\\site-packages\\pip\\_internal\\resolution\\resolvelib\n",
      "..\\venv\\Lib\\site-packages\\pip\\_internal\\resolution\\__pycache__\n",
      "..\\venv\\Lib\\site-packages\\pip\\_internal\\resolution\\legacy\\__pycache__\n",
      "..\\venv\\Lib\\site-packages\\pip\\_internal\\resolution\\resolvelib\\__pycache__\n",
      "..\\venv\\Lib\\site-packages\\pip\\_internal\\utils\\__pycache__\n",
      "..\\venv\\Lib\\site-packages\\pip\\_internal\\vcs\\__pycache__\n",
      "..\\venv\\Lib\\site-packages\\pip\\_vendor\\cachecontrol\n",
      "..\\venv\\Lib\\site-packages\\pip\\_vendor\\certifi\n",
      "..\\venv\\Lib\\site-packages\\pip\\_vendor\\chardet\n",
      "..\\venv\\Lib\\site-packages\\pip\\_vendor\\colorama\n",
      "..\\venv\\Lib\\site-packages\\pip\\_vendor\\distlib\n",
      "..\\venv\\Lib\\site-packages\\pip\\_vendor\\distro\n",
      "..\\venv\\Lib\\site-packages\\pip\\_vendor\\idna\n",
      "..\\venv\\Lib\\site-packages\\pip\\_vendor\\msgpack\n",
      "..\\venv\\Lib\\site-packages\\pip\\_vendor\\packaging\n",
      "..\\venv\\Lib\\site-packages\\pip\\_vendor\\pkg_resources\n",
      "..\\venv\\Lib\\site-packages\\pip\\_vendor\\platformdirs\n",
      "..\\venv\\Lib\\site-packages\\pip\\_vendor\\pygments\n",
      "..\\venv\\Lib\\site-packages\\pip\\_vendor\\pyparsing\n",
      "..\\venv\\Lib\\site-packages\\pip\\_vendor\\pyproject_hooks\n",
      "..\\venv\\Lib\\site-packages\\pip\\_vendor\\requests\n",
      "..\\venv\\Lib\\site-packages\\pip\\_vendor\\resolvelib\n",
      "..\\venv\\Lib\\site-packages\\pip\\_vendor\\rich\n",
      "..\\venv\\Lib\\site-packages\\pip\\_vendor\\tenacity\n",
      "..\\venv\\Lib\\site-packages\\pip\\_vendor\\tomli\n",
      "..\\venv\\Lib\\site-packages\\pip\\_vendor\\urllib3\n",
      "..\\venv\\Lib\\site-packages\\pip\\_vendor\\webencodings\n",
      "..\\venv\\Lib\\site-packages\\pip\\_vendor\\__pycache__\n",
      "..\\venv\\Lib\\site-packages\\pip\\_vendor\\cachecontrol\\caches\n",
      "..\\venv\\Lib\\site-packages\\pip\\_vendor\\cachecontrol\\__pycache__\n",
      "..\\venv\\Lib\\site-packages\\pip\\_vendor\\cachecontrol\\caches\\__pycache__\n",
      "..\\venv\\Lib\\site-packages\\pip\\_vendor\\certifi\\__pycache__\n",
      "..\\venv\\Lib\\site-packages\\pip\\_vendor\\chardet\\cli\n",
      "..\\venv\\Lib\\site-packages\\pip\\_vendor\\chardet\\metadata\n",
      "..\\venv\\Lib\\site-packages\\pip\\_vendor\\chardet\\__pycache__\n",
      "..\\venv\\Lib\\site-packages\\pip\\_vendor\\chardet\\cli\\__pycache__\n",
      "..\\venv\\Lib\\site-packages\\pip\\_vendor\\chardet\\metadata\\__pycache__\n",
      "..\\venv\\Lib\\site-packages\\pip\\_vendor\\colorama\\tests\n",
      "..\\venv\\Lib\\site-packages\\pip\\_vendor\\colorama\\__pycache__\n",
      "..\\venv\\Lib\\site-packages\\pip\\_vendor\\colorama\\tests\\__pycache__\n",
      "..\\venv\\Lib\\site-packages\\pip\\_vendor\\distlib\\__pycache__\n",
      "..\\venv\\Lib\\site-packages\\pip\\_vendor\\distro\\__pycache__\n",
      "..\\venv\\Lib\\site-packages\\pip\\_vendor\\idna\\__pycache__\n",
      "..\\venv\\Lib\\site-packages\\pip\\_vendor\\msgpack\\__pycache__\n",
      "..\\venv\\Lib\\site-packages\\pip\\_vendor\\packaging\\__pycache__\n",
      "..\\venv\\Lib\\site-packages\\pip\\_vendor\\pkg_resources\\__pycache__\n",
      "..\\venv\\Lib\\site-packages\\pip\\_vendor\\platformdirs\\__pycache__\n",
      "..\\venv\\Lib\\site-packages\\pip\\_vendor\\pygments\\filters\n",
      "..\\venv\\Lib\\site-packages\\pip\\_vendor\\pygments\\formatters\n",
      "..\\venv\\Lib\\site-packages\\pip\\_vendor\\pygments\\lexers\n",
      "..\\venv\\Lib\\site-packages\\pip\\_vendor\\pygments\\styles\n",
      "..\\venv\\Lib\\site-packages\\pip\\_vendor\\pygments\\__pycache__\n",
      "..\\venv\\Lib\\site-packages\\pip\\_vendor\\pygments\\filters\\__pycache__\n",
      "..\\venv\\Lib\\site-packages\\pip\\_vendor\\pygments\\formatters\\__pycache__\n",
      "..\\venv\\Lib\\site-packages\\pip\\_vendor\\pygments\\lexers\\__pycache__\n",
      "..\\venv\\Lib\\site-packages\\pip\\_vendor\\pygments\\styles\\__pycache__\n",
      "..\\venv\\Lib\\site-packages\\pip\\_vendor\\pyparsing\\diagram\n",
      "..\\venv\\Lib\\site-packages\\pip\\_vendor\\pyparsing\\__pycache__\n",
      "..\\venv\\Lib\\site-packages\\pip\\_vendor\\pyparsing\\diagram\\__pycache__\n",
      "..\\venv\\Lib\\site-packages\\pip\\_vendor\\pyproject_hooks\\_in_process\n",
      "..\\venv\\Lib\\site-packages\\pip\\_vendor\\pyproject_hooks\\__pycache__\n",
      "..\\venv\\Lib\\site-packages\\pip\\_vendor\\pyproject_hooks\\_in_process\\__pycache__\n",
      "..\\venv\\Lib\\site-packages\\pip\\_vendor\\requests\\__pycache__\n",
      "..\\venv\\Lib\\site-packages\\pip\\_vendor\\resolvelib\\compat\n",
      "..\\venv\\Lib\\site-packages\\pip\\_vendor\\resolvelib\\__pycache__\n",
      "..\\venv\\Lib\\site-packages\\pip\\_vendor\\resolvelib\\compat\\__pycache__\n",
      "..\\venv\\Lib\\site-packages\\pip\\_vendor\\rich\\__pycache__\n",
      "..\\venv\\Lib\\site-packages\\pip\\_vendor\\tenacity\\__pycache__\n",
      "..\\venv\\Lib\\site-packages\\pip\\_vendor\\tomli\\__pycache__\n",
      "..\\venv\\Lib\\site-packages\\pip\\_vendor\\urllib3\\contrib\n",
      "..\\venv\\Lib\\site-packages\\pip\\_vendor\\urllib3\\packages\n",
      "..\\venv\\Lib\\site-packages\\pip\\_vendor\\urllib3\\util\n",
      "..\\venv\\Lib\\site-packages\\pip\\_vendor\\urllib3\\__pycache__\n",
      "..\\venv\\Lib\\site-packages\\pip\\_vendor\\urllib3\\contrib\\_securetransport\n",
      "..\\venv\\Lib\\site-packages\\pip\\_vendor\\urllib3\\contrib\\__pycache__\n",
      "..\\venv\\Lib\\site-packages\\pip\\_vendor\\urllib3\\contrib\\_securetransport\\__pycache__\n",
      "..\\venv\\Lib\\site-packages\\pip\\_vendor\\urllib3\\packages\\backports\n",
      "..\\venv\\Lib\\site-packages\\pip\\_vendor\\urllib3\\packages\\__pycache__\n",
      "..\\venv\\Lib\\site-packages\\pip\\_vendor\\urllib3\\packages\\backports\\__pycache__\n",
      "..\\venv\\Lib\\site-packages\\pip\\_vendor\\urllib3\\util\\__pycache__\n",
      "..\\venv\\Lib\\site-packages\\pip\\_vendor\\webencodings\\__pycache__\n",
      "..\\venv\\Lib\\site-packages\\pkg_resources\\extern\n",
      "..\\venv\\Lib\\site-packages\\pkg_resources\\tests\n",
      "..\\venv\\Lib\\site-packages\\pkg_resources\\_vendor\n",
      "..\\venv\\Lib\\site-packages\\pkg_resources\\__pycache__\n",
      "..\\venv\\Lib\\site-packages\\pkg_resources\\extern\\__pycache__\n",
      "..\\venv\\Lib\\site-packages\\pkg_resources\\tests\\data\n",
      "..\\venv\\Lib\\site-packages\\pkg_resources\\tests\\data\\my-test-package-source\n",
      "..\\venv\\Lib\\site-packages\\pkg_resources\\tests\\data\\my-test-package-source\\__pycache__\n",
      "..\\venv\\Lib\\site-packages\\pkg_resources\\_vendor\\packaging\n",
      "..\\venv\\Lib\\site-packages\\pkg_resources\\_vendor\\__pycache__\n",
      "..\\venv\\Lib\\site-packages\\pkg_resources\\_vendor\\packaging\\__pycache__\n",
      "..\\venv\\Lib\\site-packages\\setuptools\\command\n",
      "..\\venv\\Lib\\site-packages\\setuptools\\extern\n",
      "..\\venv\\Lib\\site-packages\\setuptools\\_distutils\n",
      "..\\venv\\Lib\\site-packages\\setuptools\\_vendor\n",
      "..\\venv\\Lib\\site-packages\\setuptools\\__pycache__\n",
      "..\\venv\\Lib\\site-packages\\setuptools\\command\\__pycache__\n",
      "..\\venv\\Lib\\site-packages\\setuptools\\extern\\__pycache__\n",
      "..\\venv\\Lib\\site-packages\\setuptools\\_distutils\\command\n",
      "..\\venv\\Lib\\site-packages\\setuptools\\_distutils\\__pycache__\n",
      "..\\venv\\Lib\\site-packages\\setuptools\\_distutils\\command\\__pycache__\n",
      "..\\venv\\Lib\\site-packages\\setuptools\\_vendor\\packaging\n",
      "..\\venv\\Lib\\site-packages\\setuptools\\_vendor\\__pycache__\n",
      "..\\venv\\Lib\\site-packages\\setuptools\\_vendor\\packaging\\__pycache__\n",
      "..\\venv\\Lib\\site-packages\\_distutils_hack\\__pycache__\n"
     ]
    }
   ],
   "source": [
    "import os\n",
    "for root, dirs, files in os.walk(\"..\", topdown=True):\n",
    "    for name in dirs:\n",
    "        print(os.path.join(root, name))\n"
   ]
  },
  {
   "cell_type": "code",
   "execution_count": 6,
   "id": "03e86c60-8a0e-40f2-89ae-7d706caee118",
   "metadata": {},
   "outputs": [
    {
     "name": "stdout",
     "output_type": "stream",
     "text": [
      "Found 15000 images belonging to 5 classes.\n"
     ]
    }
   ],
   "source": [
    "from tensorflow.keras.preprocessing.image import ImageDataGenerator\n",
    "\n",
    "val_datagen = ImageDataGenerator(rescale=1./255)\n",
    "\n",
    "val_generator = val_datagen.flow_from_directory(\n",
    "    \"../data/Rice_Image_Dataset_split/validation\",  # <-- correct path\n",
    "    target_size=(224, 224),                         # or the size used during training\n",
    "    batch_size=32,\n",
    "    class_mode='categorical',\n",
    "    shuffle=False\n",
    ")\n"
   ]
  },
  {
   "cell_type": "code",
   "execution_count": 7,
   "id": "daf28827-8261-4685-910b-4a5383915be1",
   "metadata": {},
   "outputs": [
    {
     "ename": "InvalidArgumentError",
     "evalue": "Graph execution error:\n\nDetected at node 'sequential_1/flatten_1/Reshape' defined at (most recent call last):\n    File \"C:\\Users\\saium\\.conda\\envs\\tf_env\\lib\\runpy.py\", line 194, in _run_module_as_main\n      return _run_code(code, main_globals, None,\n    File \"C:\\Users\\saium\\.conda\\envs\\tf_env\\lib\\runpy.py\", line 87, in _run_code\n      exec(code, run_globals)\n    File \"C:\\Users\\saium\\.conda\\envs\\tf_env\\lib\\site-packages\\ipykernel_launcher.py\", line 18, in <module>\n      app.launch_new_instance()\n    File \"C:\\Users\\saium\\.conda\\envs\\tf_env\\lib\\site-packages\\traitlets\\config\\application.py\", line 1075, in launch_instance\n      app.start()\n    File \"C:\\Users\\saium\\.conda\\envs\\tf_env\\lib\\site-packages\\ipykernel\\kernelapp.py\", line 739, in start\n      self.io_loop.start()\n    File \"C:\\Users\\saium\\.conda\\envs\\tf_env\\lib\\site-packages\\tornado\\platform\\asyncio.py\", line 205, in start\n      self.asyncio_loop.run_forever()\n    File \"C:\\Users\\saium\\.conda\\envs\\tf_env\\lib\\asyncio\\base_events.py\", line 570, in run_forever\n      self._run_once()\n    File \"C:\\Users\\saium\\.conda\\envs\\tf_env\\lib\\asyncio\\base_events.py\", line 1859, in _run_once\n      handle._run()\n    File \"C:\\Users\\saium\\.conda\\envs\\tf_env\\lib\\asyncio\\events.py\", line 81, in _run\n      self._context.run(self._callback, *self._args)\n    File \"C:\\Users\\saium\\.conda\\envs\\tf_env\\lib\\site-packages\\ipykernel\\kernelbase.py\", line 545, in dispatch_queue\n      await self.process_one()\n    File \"C:\\Users\\saium\\.conda\\envs\\tf_env\\lib\\site-packages\\ipykernel\\kernelbase.py\", line 534, in process_one\n      await dispatch(*args)\n    File \"C:\\Users\\saium\\.conda\\envs\\tf_env\\lib\\site-packages\\ipykernel\\kernelbase.py\", line 437, in dispatch_shell\n      await result\n    File \"C:\\Users\\saium\\.conda\\envs\\tf_env\\lib\\site-packages\\ipykernel\\ipkernel.py\", line 362, in execute_request\n      await super().execute_request(stream, ident, parent)\n    File \"C:\\Users\\saium\\.conda\\envs\\tf_env\\lib\\site-packages\\ipykernel\\kernelbase.py\", line 778, in execute_request\n      reply_content = await reply_content\n    File \"C:\\Users\\saium\\.conda\\envs\\tf_env\\lib\\site-packages\\ipykernel\\ipkernel.py\", line 449, in do_execute\n      res = shell.run_cell(\n    File \"C:\\Users\\saium\\.conda\\envs\\tf_env\\lib\\site-packages\\ipykernel\\zmqshell.py\", line 549, in run_cell\n      return super().run_cell(*args, **kwargs)\n    File \"C:\\Users\\saium\\.conda\\envs\\tf_env\\lib\\site-packages\\IPython\\core\\interactiveshell.py\", line 3009, in run_cell\n      result = self._run_cell(\n    File \"C:\\Users\\saium\\.conda\\envs\\tf_env\\lib\\site-packages\\IPython\\core\\interactiveshell.py\", line 3064, in _run_cell\n      result = runner(coro)\n    File \"C:\\Users\\saium\\.conda\\envs\\tf_env\\lib\\site-packages\\IPython\\core\\async_helpers.py\", line 129, in _pseudo_sync_runner\n      coro.send(None)\n    File \"C:\\Users\\saium\\.conda\\envs\\tf_env\\lib\\site-packages\\IPython\\core\\interactiveshell.py\", line 3269, in run_cell_async\n      has_raised = await self.run_ast_nodes(code_ast.body, cell_name,\n    File \"C:\\Users\\saium\\.conda\\envs\\tf_env\\lib\\site-packages\\IPython\\core\\interactiveshell.py\", line 3448, in run_ast_nodes\n      if await self.run_code(code, result, async_=asy):\n    File \"C:\\Users\\saium\\.conda\\envs\\tf_env\\lib\\site-packages\\IPython\\core\\interactiveshell.py\", line 3508, in run_code\n      exec(code_obj, self.user_global_ns, self.user_ns)\n    File \"C:\\Users\\saium\\AppData\\Local\\Temp\\ipykernel_70004\\3427472792.py\", line 1, in <module>\n      val_loss, val_acc = model.evaluate(val_generator)\n    File \"C:\\Users\\saium\\.conda\\envs\\tf_env\\lib\\site-packages\\keras\\utils\\traceback_utils.py\", line 65, in error_handler\n      return fn(*args, **kwargs)\n    File \"C:\\Users\\saium\\.conda\\envs\\tf_env\\lib\\site-packages\\keras\\engine\\training.py\", line 1947, in evaluate\n      tmp_logs = self.test_function(iterator)\n    File \"C:\\Users\\saium\\.conda\\envs\\tf_env\\lib\\site-packages\\keras\\engine\\training.py\", line 1727, in test_function\n      return step_function(self, iterator)\n    File \"C:\\Users\\saium\\.conda\\envs\\tf_env\\lib\\site-packages\\keras\\engine\\training.py\", line 1713, in step_function\n      outputs = model.distribute_strategy.run(run_step, args=(data,))\n    File \"C:\\Users\\saium\\.conda\\envs\\tf_env\\lib\\site-packages\\keras\\engine\\training.py\", line 1701, in run_step\n      outputs = model.test_step(data)\n    File \"C:\\Users\\saium\\.conda\\envs\\tf_env\\lib\\site-packages\\keras\\engine\\training.py\", line 1665, in test_step\n      y_pred = self(x, training=False)\n    File \"C:\\Users\\saium\\.conda\\envs\\tf_env\\lib\\site-packages\\keras\\utils\\traceback_utils.py\", line 65, in error_handler\n      return fn(*args, **kwargs)\n    File \"C:\\Users\\saium\\.conda\\envs\\tf_env\\lib\\site-packages\\keras\\engine\\training.py\", line 557, in __call__\n      return super().__call__(*args, **kwargs)\n    File \"C:\\Users\\saium\\.conda\\envs\\tf_env\\lib\\site-packages\\keras\\utils\\traceback_utils.py\", line 65, in error_handler\n      return fn(*args, **kwargs)\n    File \"C:\\Users\\saium\\.conda\\envs\\tf_env\\lib\\site-packages\\keras\\engine\\base_layer.py\", line 1097, in __call__\n      outputs = call_fn(inputs, *args, **kwargs)\n    File \"C:\\Users\\saium\\.conda\\envs\\tf_env\\lib\\site-packages\\keras\\utils\\traceback_utils.py\", line 96, in error_handler\n      return fn(*args, **kwargs)\n    File \"C:\\Users\\saium\\.conda\\envs\\tf_env\\lib\\site-packages\\keras\\engine\\sequential.py\", line 410, in call\n      return super().call(inputs, training=training, mask=mask)\n    File \"C:\\Users\\saium\\.conda\\envs\\tf_env\\lib\\site-packages\\keras\\engine\\functional.py\", line 510, in call\n      return self._run_internal_graph(inputs, training=training, mask=mask)\n    File \"C:\\Users\\saium\\.conda\\envs\\tf_env\\lib\\site-packages\\keras\\engine\\functional.py\", line 667, in _run_internal_graph\n      outputs = node.layer(*args, **kwargs)\n    File \"C:\\Users\\saium\\.conda\\envs\\tf_env\\lib\\site-packages\\keras\\utils\\traceback_utils.py\", line 65, in error_handler\n      return fn(*args, **kwargs)\n    File \"C:\\Users\\saium\\.conda\\envs\\tf_env\\lib\\site-packages\\keras\\engine\\base_layer.py\", line 1097, in __call__\n      outputs = call_fn(inputs, *args, **kwargs)\n    File \"C:\\Users\\saium\\.conda\\envs\\tf_env\\lib\\site-packages\\keras\\utils\\traceback_utils.py\", line 96, in error_handler\n      return fn(*args, **kwargs)\n    File \"C:\\Users\\saium\\.conda\\envs\\tf_env\\lib\\site-packages\\keras\\layers\\reshaping\\flatten.py\", line 104, in call\n      return tf.reshape(inputs, flattened_shape)\nNode: 'sequential_1/flatten_1/Reshape'\nInput to reshape is a tensor with 5971968 values, but the requested shape requires a multiple of 12544\n\t [[{{node sequential_1/flatten_1/Reshape}}]] [Op:__inference_test_function_486]",
     "output_type": "error",
     "traceback": [
      "\u001b[1;31m---------------------------------------------------------------------------\u001b[0m",
      "\u001b[1;31mInvalidArgumentError\u001b[0m                      Traceback (most recent call last)",
      "Cell \u001b[1;32mIn[7], line 1\u001b[0m\n\u001b[1;32m----> 1\u001b[0m val_loss, val_acc \u001b[38;5;241m=\u001b[39m \u001b[43mmodel\u001b[49m\u001b[38;5;241;43m.\u001b[39;49m\u001b[43mevaluate\u001b[49m\u001b[43m(\u001b[49m\u001b[43mval_generator\u001b[49m\u001b[43m)\u001b[49m\n\u001b[0;32m      2\u001b[0m \u001b[38;5;28mprint\u001b[39m(\u001b[38;5;124mf\u001b[39m\u001b[38;5;124m\"\u001b[39m\u001b[38;5;124mValidation Accuracy: \u001b[39m\u001b[38;5;132;01m{\u001b[39;00mval_acc\u001b[38;5;241m*\u001b[39m\u001b[38;5;241m100\u001b[39m\u001b[38;5;132;01m:\u001b[39;00m\u001b[38;5;124m.2f\u001b[39m\u001b[38;5;132;01m}\u001b[39;00m\u001b[38;5;124m%\u001b[39m\u001b[38;5;124m\"\u001b[39m)\n\u001b[0;32m      3\u001b[0m \u001b[38;5;28mprint\u001b[39m(\u001b[38;5;124mf\u001b[39m\u001b[38;5;124m\"\u001b[39m\u001b[38;5;124mValidation Loss: \u001b[39m\u001b[38;5;132;01m{\u001b[39;00mval_loss\u001b[38;5;132;01m:\u001b[39;00m\u001b[38;5;124m.4f\u001b[39m\u001b[38;5;132;01m}\u001b[39;00m\u001b[38;5;124m\"\u001b[39m)\n",
      "File \u001b[1;32m~\\.conda\\envs\\tf_env\\lib\\site-packages\\keras\\utils\\traceback_utils.py:70\u001b[0m, in \u001b[0;36mfilter_traceback.<locals>.error_handler\u001b[1;34m(*args, **kwargs)\u001b[0m\n\u001b[0;32m     67\u001b[0m     filtered_tb \u001b[38;5;241m=\u001b[39m _process_traceback_frames(e\u001b[38;5;241m.\u001b[39m__traceback__)\n\u001b[0;32m     68\u001b[0m     \u001b[38;5;66;03m# To get the full stack trace, call:\u001b[39;00m\n\u001b[0;32m     69\u001b[0m     \u001b[38;5;66;03m# `tf.debugging.disable_traceback_filtering()`\u001b[39;00m\n\u001b[1;32m---> 70\u001b[0m     \u001b[38;5;28;01mraise\u001b[39;00m e\u001b[38;5;241m.\u001b[39mwith_traceback(filtered_tb) \u001b[38;5;28;01mfrom\u001b[39;00m \u001b[38;5;28;01mNone\u001b[39;00m\n\u001b[0;32m     71\u001b[0m \u001b[38;5;28;01mfinally\u001b[39;00m:\n\u001b[0;32m     72\u001b[0m     \u001b[38;5;28;01mdel\u001b[39;00m filtered_tb\n",
      "File \u001b[1;32m~\\.conda\\envs\\tf_env\\lib\\site-packages\\tensorflow\\python\\eager\\execute.py:54\u001b[0m, in \u001b[0;36mquick_execute\u001b[1;34m(op_name, num_outputs, inputs, attrs, ctx, name)\u001b[0m\n\u001b[0;32m     52\u001b[0m \u001b[38;5;28;01mtry\u001b[39;00m:\n\u001b[0;32m     53\u001b[0m   ctx\u001b[38;5;241m.\u001b[39mensure_initialized()\n\u001b[1;32m---> 54\u001b[0m   tensors \u001b[38;5;241m=\u001b[39m pywrap_tfe\u001b[38;5;241m.\u001b[39mTFE_Py_Execute(ctx\u001b[38;5;241m.\u001b[39m_handle, device_name, op_name,\n\u001b[0;32m     55\u001b[0m                                       inputs, attrs, num_outputs)\n\u001b[0;32m     56\u001b[0m \u001b[38;5;28;01mexcept\u001b[39;00m core\u001b[38;5;241m.\u001b[39m_NotOkStatusException \u001b[38;5;28;01mas\u001b[39;00m e:\n\u001b[0;32m     57\u001b[0m   \u001b[38;5;28;01mif\u001b[39;00m name \u001b[38;5;129;01mis\u001b[39;00m \u001b[38;5;129;01mnot\u001b[39;00m \u001b[38;5;28;01mNone\u001b[39;00m:\n",
      "\u001b[1;31mInvalidArgumentError\u001b[0m: Graph execution error:\n\nDetected at node 'sequential_1/flatten_1/Reshape' defined at (most recent call last):\n    File \"C:\\Users\\saium\\.conda\\envs\\tf_env\\lib\\runpy.py\", line 194, in _run_module_as_main\n      return _run_code(code, main_globals, None,\n    File \"C:\\Users\\saium\\.conda\\envs\\tf_env\\lib\\runpy.py\", line 87, in _run_code\n      exec(code, run_globals)\n    File \"C:\\Users\\saium\\.conda\\envs\\tf_env\\lib\\site-packages\\ipykernel_launcher.py\", line 18, in <module>\n      app.launch_new_instance()\n    File \"C:\\Users\\saium\\.conda\\envs\\tf_env\\lib\\site-packages\\traitlets\\config\\application.py\", line 1075, in launch_instance\n      app.start()\n    File \"C:\\Users\\saium\\.conda\\envs\\tf_env\\lib\\site-packages\\ipykernel\\kernelapp.py\", line 739, in start\n      self.io_loop.start()\n    File \"C:\\Users\\saium\\.conda\\envs\\tf_env\\lib\\site-packages\\tornado\\platform\\asyncio.py\", line 205, in start\n      self.asyncio_loop.run_forever()\n    File \"C:\\Users\\saium\\.conda\\envs\\tf_env\\lib\\asyncio\\base_events.py\", line 570, in run_forever\n      self._run_once()\n    File \"C:\\Users\\saium\\.conda\\envs\\tf_env\\lib\\asyncio\\base_events.py\", line 1859, in _run_once\n      handle._run()\n    File \"C:\\Users\\saium\\.conda\\envs\\tf_env\\lib\\asyncio\\events.py\", line 81, in _run\n      self._context.run(self._callback, *self._args)\n    File \"C:\\Users\\saium\\.conda\\envs\\tf_env\\lib\\site-packages\\ipykernel\\kernelbase.py\", line 545, in dispatch_queue\n      await self.process_one()\n    File \"C:\\Users\\saium\\.conda\\envs\\tf_env\\lib\\site-packages\\ipykernel\\kernelbase.py\", line 534, in process_one\n      await dispatch(*args)\n    File \"C:\\Users\\saium\\.conda\\envs\\tf_env\\lib\\site-packages\\ipykernel\\kernelbase.py\", line 437, in dispatch_shell\n      await result\n    File \"C:\\Users\\saium\\.conda\\envs\\tf_env\\lib\\site-packages\\ipykernel\\ipkernel.py\", line 362, in execute_request\n      await super().execute_request(stream, ident, parent)\n    File \"C:\\Users\\saium\\.conda\\envs\\tf_env\\lib\\site-packages\\ipykernel\\kernelbase.py\", line 778, in execute_request\n      reply_content = await reply_content\n    File \"C:\\Users\\saium\\.conda\\envs\\tf_env\\lib\\site-packages\\ipykernel\\ipkernel.py\", line 449, in do_execute\n      res = shell.run_cell(\n    File \"C:\\Users\\saium\\.conda\\envs\\tf_env\\lib\\site-packages\\ipykernel\\zmqshell.py\", line 549, in run_cell\n      return super().run_cell(*args, **kwargs)\n    File \"C:\\Users\\saium\\.conda\\envs\\tf_env\\lib\\site-packages\\IPython\\core\\interactiveshell.py\", line 3009, in run_cell\n      result = self._run_cell(\n    File \"C:\\Users\\saium\\.conda\\envs\\tf_env\\lib\\site-packages\\IPython\\core\\interactiveshell.py\", line 3064, in _run_cell\n      result = runner(coro)\n    File \"C:\\Users\\saium\\.conda\\envs\\tf_env\\lib\\site-packages\\IPython\\core\\async_helpers.py\", line 129, in _pseudo_sync_runner\n      coro.send(None)\n    File \"C:\\Users\\saium\\.conda\\envs\\tf_env\\lib\\site-packages\\IPython\\core\\interactiveshell.py\", line 3269, in run_cell_async\n      has_raised = await self.run_ast_nodes(code_ast.body, cell_name,\n    File \"C:\\Users\\saium\\.conda\\envs\\tf_env\\lib\\site-packages\\IPython\\core\\interactiveshell.py\", line 3448, in run_ast_nodes\n      if await self.run_code(code, result, async_=asy):\n    File \"C:\\Users\\saium\\.conda\\envs\\tf_env\\lib\\site-packages\\IPython\\core\\interactiveshell.py\", line 3508, in run_code\n      exec(code_obj, self.user_global_ns, self.user_ns)\n    File \"C:\\Users\\saium\\AppData\\Local\\Temp\\ipykernel_70004\\3427472792.py\", line 1, in <module>\n      val_loss, val_acc = model.evaluate(val_generator)\n    File \"C:\\Users\\saium\\.conda\\envs\\tf_env\\lib\\site-packages\\keras\\utils\\traceback_utils.py\", line 65, in error_handler\n      return fn(*args, **kwargs)\n    File \"C:\\Users\\saium\\.conda\\envs\\tf_env\\lib\\site-packages\\keras\\engine\\training.py\", line 1947, in evaluate\n      tmp_logs = self.test_function(iterator)\n    File \"C:\\Users\\saium\\.conda\\envs\\tf_env\\lib\\site-packages\\keras\\engine\\training.py\", line 1727, in test_function\n      return step_function(self, iterator)\n    File \"C:\\Users\\saium\\.conda\\envs\\tf_env\\lib\\site-packages\\keras\\engine\\training.py\", line 1713, in step_function\n      outputs = model.distribute_strategy.run(run_step, args=(data,))\n    File \"C:\\Users\\saium\\.conda\\envs\\tf_env\\lib\\site-packages\\keras\\engine\\training.py\", line 1701, in run_step\n      outputs = model.test_step(data)\n    File \"C:\\Users\\saium\\.conda\\envs\\tf_env\\lib\\site-packages\\keras\\engine\\training.py\", line 1665, in test_step\n      y_pred = self(x, training=False)\n    File \"C:\\Users\\saium\\.conda\\envs\\tf_env\\lib\\site-packages\\keras\\utils\\traceback_utils.py\", line 65, in error_handler\n      return fn(*args, **kwargs)\n    File \"C:\\Users\\saium\\.conda\\envs\\tf_env\\lib\\site-packages\\keras\\engine\\training.py\", line 557, in __call__\n      return super().__call__(*args, **kwargs)\n    File \"C:\\Users\\saium\\.conda\\envs\\tf_env\\lib\\site-packages\\keras\\utils\\traceback_utils.py\", line 65, in error_handler\n      return fn(*args, **kwargs)\n    File \"C:\\Users\\saium\\.conda\\envs\\tf_env\\lib\\site-packages\\keras\\engine\\base_layer.py\", line 1097, in __call__\n      outputs = call_fn(inputs, *args, **kwargs)\n    File \"C:\\Users\\saium\\.conda\\envs\\tf_env\\lib\\site-packages\\keras\\utils\\traceback_utils.py\", line 96, in error_handler\n      return fn(*args, **kwargs)\n    File \"C:\\Users\\saium\\.conda\\envs\\tf_env\\lib\\site-packages\\keras\\engine\\sequential.py\", line 410, in call\n      return super().call(inputs, training=training, mask=mask)\n    File \"C:\\Users\\saium\\.conda\\envs\\tf_env\\lib\\site-packages\\keras\\engine\\functional.py\", line 510, in call\n      return self._run_internal_graph(inputs, training=training, mask=mask)\n    File \"C:\\Users\\saium\\.conda\\envs\\tf_env\\lib\\site-packages\\keras\\engine\\functional.py\", line 667, in _run_internal_graph\n      outputs = node.layer(*args, **kwargs)\n    File \"C:\\Users\\saium\\.conda\\envs\\tf_env\\lib\\site-packages\\keras\\utils\\traceback_utils.py\", line 65, in error_handler\n      return fn(*args, **kwargs)\n    File \"C:\\Users\\saium\\.conda\\envs\\tf_env\\lib\\site-packages\\keras\\engine\\base_layer.py\", line 1097, in __call__\n      outputs = call_fn(inputs, *args, **kwargs)\n    File \"C:\\Users\\saium\\.conda\\envs\\tf_env\\lib\\site-packages\\keras\\utils\\traceback_utils.py\", line 96, in error_handler\n      return fn(*args, **kwargs)\n    File \"C:\\Users\\saium\\.conda\\envs\\tf_env\\lib\\site-packages\\keras\\layers\\reshaping\\flatten.py\", line 104, in call\n      return tf.reshape(inputs, flattened_shape)\nNode: 'sequential_1/flatten_1/Reshape'\nInput to reshape is a tensor with 5971968 values, but the requested shape requires a multiple of 12544\n\t [[{{node sequential_1/flatten_1/Reshape}}]] [Op:__inference_test_function_486]"
     ]
    }
   ],
   "source": [
    "val_loss, val_acc = model.evaluate(val_generator)\n",
    "print(f\"Validation Accuracy: {val_acc*100:.2f}%\")\n",
    "print(f\"Validation Loss: {val_loss:.4f}\")\n"
   ]
  },
  {
   "cell_type": "code",
   "execution_count": 8,
   "id": "ac4078c3-748a-4c7f-b99f-cb948220706b",
   "metadata": {},
   "outputs": [
    {
     "name": "stdout",
     "output_type": "stream",
     "text": [
      "Found 15000 images belonging to 5 classes.\n"
     ]
    }
   ],
   "source": [
    "val_generator = val_datagen.flow_from_directory(\n",
    "    \"../data/Rice_Image_Dataset_split/validation\",\n",
    "    target_size=(128, 128),   # ← change this to match training size\n",
    "    batch_size=32,\n",
    "    class_mode='categorical',\n",
    "    shuffle=False\n",
    ")\n"
   ]
  },
  {
   "cell_type": "code",
   "execution_count": 9,
   "id": "72f0bb52-e701-49e0-907a-2216e0cfb803",
   "metadata": {},
   "outputs": [
    {
     "ename": "InvalidArgumentError",
     "evalue": "Graph execution error:\n\nDetected at node 'sequential_1/flatten_1/Reshape' defined at (most recent call last):\n    File \"C:\\Users\\saium\\.conda\\envs\\tf_env\\lib\\runpy.py\", line 194, in _run_module_as_main\n      return _run_code(code, main_globals, None,\n    File \"C:\\Users\\saium\\.conda\\envs\\tf_env\\lib\\runpy.py\", line 87, in _run_code\n      exec(code, run_globals)\n    File \"C:\\Users\\saium\\.conda\\envs\\tf_env\\lib\\site-packages\\ipykernel_launcher.py\", line 18, in <module>\n      app.launch_new_instance()\n    File \"C:\\Users\\saium\\.conda\\envs\\tf_env\\lib\\site-packages\\traitlets\\config\\application.py\", line 1075, in launch_instance\n      app.start()\n    File \"C:\\Users\\saium\\.conda\\envs\\tf_env\\lib\\site-packages\\ipykernel\\kernelapp.py\", line 739, in start\n      self.io_loop.start()\n    File \"C:\\Users\\saium\\.conda\\envs\\tf_env\\lib\\site-packages\\tornado\\platform\\asyncio.py\", line 205, in start\n      self.asyncio_loop.run_forever()\n    File \"C:\\Users\\saium\\.conda\\envs\\tf_env\\lib\\asyncio\\base_events.py\", line 570, in run_forever\n      self._run_once()\n    File \"C:\\Users\\saium\\.conda\\envs\\tf_env\\lib\\asyncio\\base_events.py\", line 1859, in _run_once\n      handle._run()\n    File \"C:\\Users\\saium\\.conda\\envs\\tf_env\\lib\\asyncio\\events.py\", line 81, in _run\n      self._context.run(self._callback, *self._args)\n    File \"C:\\Users\\saium\\.conda\\envs\\tf_env\\lib\\site-packages\\ipykernel\\kernelbase.py\", line 545, in dispatch_queue\n      await self.process_one()\n    File \"C:\\Users\\saium\\.conda\\envs\\tf_env\\lib\\site-packages\\ipykernel\\kernelbase.py\", line 534, in process_one\n      await dispatch(*args)\n    File \"C:\\Users\\saium\\.conda\\envs\\tf_env\\lib\\site-packages\\ipykernel\\kernelbase.py\", line 437, in dispatch_shell\n      await result\n    File \"C:\\Users\\saium\\.conda\\envs\\tf_env\\lib\\site-packages\\ipykernel\\ipkernel.py\", line 362, in execute_request\n      await super().execute_request(stream, ident, parent)\n    File \"C:\\Users\\saium\\.conda\\envs\\tf_env\\lib\\site-packages\\ipykernel\\kernelbase.py\", line 778, in execute_request\n      reply_content = await reply_content\n    File \"C:\\Users\\saium\\.conda\\envs\\tf_env\\lib\\site-packages\\ipykernel\\ipkernel.py\", line 449, in do_execute\n      res = shell.run_cell(\n    File \"C:\\Users\\saium\\.conda\\envs\\tf_env\\lib\\site-packages\\ipykernel\\zmqshell.py\", line 549, in run_cell\n      return super().run_cell(*args, **kwargs)\n    File \"C:\\Users\\saium\\.conda\\envs\\tf_env\\lib\\site-packages\\IPython\\core\\interactiveshell.py\", line 3009, in run_cell\n      result = self._run_cell(\n    File \"C:\\Users\\saium\\.conda\\envs\\tf_env\\lib\\site-packages\\IPython\\core\\interactiveshell.py\", line 3064, in _run_cell\n      result = runner(coro)\n    File \"C:\\Users\\saium\\.conda\\envs\\tf_env\\lib\\site-packages\\IPython\\core\\async_helpers.py\", line 129, in _pseudo_sync_runner\n      coro.send(None)\n    File \"C:\\Users\\saium\\.conda\\envs\\tf_env\\lib\\site-packages\\IPython\\core\\interactiveshell.py\", line 3269, in run_cell_async\n      has_raised = await self.run_ast_nodes(code_ast.body, cell_name,\n    File \"C:\\Users\\saium\\.conda\\envs\\tf_env\\lib\\site-packages\\IPython\\core\\interactiveshell.py\", line 3448, in run_ast_nodes\n      if await self.run_code(code, result, async_=asy):\n    File \"C:\\Users\\saium\\.conda\\envs\\tf_env\\lib\\site-packages\\IPython\\core\\interactiveshell.py\", line 3508, in run_code\n      exec(code_obj, self.user_global_ns, self.user_ns)\n    File \"C:\\Users\\saium\\AppData\\Local\\Temp\\ipykernel_70004\\3427472792.py\", line 1, in <module>\n      val_loss, val_acc = model.evaluate(val_generator)\n    File \"C:\\Users\\saium\\.conda\\envs\\tf_env\\lib\\site-packages\\keras\\utils\\traceback_utils.py\", line 65, in error_handler\n      return fn(*args, **kwargs)\n    File \"C:\\Users\\saium\\.conda\\envs\\tf_env\\lib\\site-packages\\keras\\engine\\training.py\", line 1947, in evaluate\n      tmp_logs = self.test_function(iterator)\n    File \"C:\\Users\\saium\\.conda\\envs\\tf_env\\lib\\site-packages\\keras\\engine\\training.py\", line 1727, in test_function\n      return step_function(self, iterator)\n    File \"C:\\Users\\saium\\.conda\\envs\\tf_env\\lib\\site-packages\\keras\\engine\\training.py\", line 1713, in step_function\n      outputs = model.distribute_strategy.run(run_step, args=(data,))\n    File \"C:\\Users\\saium\\.conda\\envs\\tf_env\\lib\\site-packages\\keras\\engine\\training.py\", line 1701, in run_step\n      outputs = model.test_step(data)\n    File \"C:\\Users\\saium\\.conda\\envs\\tf_env\\lib\\site-packages\\keras\\engine\\training.py\", line 1665, in test_step\n      y_pred = self(x, training=False)\n    File \"C:\\Users\\saium\\.conda\\envs\\tf_env\\lib\\site-packages\\keras\\utils\\traceback_utils.py\", line 65, in error_handler\n      return fn(*args, **kwargs)\n    File \"C:\\Users\\saium\\.conda\\envs\\tf_env\\lib\\site-packages\\keras\\engine\\training.py\", line 557, in __call__\n      return super().__call__(*args, **kwargs)\n    File \"C:\\Users\\saium\\.conda\\envs\\tf_env\\lib\\site-packages\\keras\\utils\\traceback_utils.py\", line 65, in error_handler\n      return fn(*args, **kwargs)\n    File \"C:\\Users\\saium\\.conda\\envs\\tf_env\\lib\\site-packages\\keras\\engine\\base_layer.py\", line 1097, in __call__\n      outputs = call_fn(inputs, *args, **kwargs)\n    File \"C:\\Users\\saium\\.conda\\envs\\tf_env\\lib\\site-packages\\keras\\utils\\traceback_utils.py\", line 96, in error_handler\n      return fn(*args, **kwargs)\n    File \"C:\\Users\\saium\\.conda\\envs\\tf_env\\lib\\site-packages\\keras\\engine\\sequential.py\", line 410, in call\n      return super().call(inputs, training=training, mask=mask)\n    File \"C:\\Users\\saium\\.conda\\envs\\tf_env\\lib\\site-packages\\keras\\engine\\functional.py\", line 510, in call\n      return self._run_internal_graph(inputs, training=training, mask=mask)\n    File \"C:\\Users\\saium\\.conda\\envs\\tf_env\\lib\\site-packages\\keras\\engine\\functional.py\", line 667, in _run_internal_graph\n      outputs = node.layer(*args, **kwargs)\n    File \"C:\\Users\\saium\\.conda\\envs\\tf_env\\lib\\site-packages\\keras\\utils\\traceback_utils.py\", line 65, in error_handler\n      return fn(*args, **kwargs)\n    File \"C:\\Users\\saium\\.conda\\envs\\tf_env\\lib\\site-packages\\keras\\engine\\base_layer.py\", line 1097, in __call__\n      outputs = call_fn(inputs, *args, **kwargs)\n    File \"C:\\Users\\saium\\.conda\\envs\\tf_env\\lib\\site-packages\\keras\\utils\\traceback_utils.py\", line 96, in error_handler\n      return fn(*args, **kwargs)\n    File \"C:\\Users\\saium\\.conda\\envs\\tf_env\\lib\\site-packages\\keras\\layers\\reshaping\\flatten.py\", line 104, in call\n      return tf.reshape(inputs, flattened_shape)\nNode: 'sequential_1/flatten_1/Reshape'\nInput to reshape is a tensor with 1843200 values, but the requested shape requires a multiple of 12544\n\t [[{{node sequential_1/flatten_1/Reshape}}]] [Op:__inference_test_function_486]",
     "output_type": "error",
     "traceback": [
      "\u001b[1;31m---------------------------------------------------------------------------\u001b[0m",
      "\u001b[1;31mInvalidArgumentError\u001b[0m                      Traceback (most recent call last)",
      "Cell \u001b[1;32mIn[9], line 1\u001b[0m\n\u001b[1;32m----> 1\u001b[0m val_loss, val_acc \u001b[38;5;241m=\u001b[39m \u001b[43mmodel\u001b[49m\u001b[38;5;241;43m.\u001b[39;49m\u001b[43mevaluate\u001b[49m\u001b[43m(\u001b[49m\u001b[43mval_generator\u001b[49m\u001b[43m)\u001b[49m\n\u001b[0;32m      2\u001b[0m \u001b[38;5;28mprint\u001b[39m(\u001b[38;5;124mf\u001b[39m\u001b[38;5;124m\"\u001b[39m\u001b[38;5;124mValidation Accuracy: \u001b[39m\u001b[38;5;132;01m{\u001b[39;00mval_acc\u001b[38;5;241m*\u001b[39m\u001b[38;5;241m100\u001b[39m\u001b[38;5;132;01m:\u001b[39;00m\u001b[38;5;124m.2f\u001b[39m\u001b[38;5;132;01m}\u001b[39;00m\u001b[38;5;124m%\u001b[39m\u001b[38;5;124m\"\u001b[39m)\n",
      "File \u001b[1;32m~\\.conda\\envs\\tf_env\\lib\\site-packages\\keras\\utils\\traceback_utils.py:70\u001b[0m, in \u001b[0;36mfilter_traceback.<locals>.error_handler\u001b[1;34m(*args, **kwargs)\u001b[0m\n\u001b[0;32m     67\u001b[0m     filtered_tb \u001b[38;5;241m=\u001b[39m _process_traceback_frames(e\u001b[38;5;241m.\u001b[39m__traceback__)\n\u001b[0;32m     68\u001b[0m     \u001b[38;5;66;03m# To get the full stack trace, call:\u001b[39;00m\n\u001b[0;32m     69\u001b[0m     \u001b[38;5;66;03m# `tf.debugging.disable_traceback_filtering()`\u001b[39;00m\n\u001b[1;32m---> 70\u001b[0m     \u001b[38;5;28;01mraise\u001b[39;00m e\u001b[38;5;241m.\u001b[39mwith_traceback(filtered_tb) \u001b[38;5;28;01mfrom\u001b[39;00m \u001b[38;5;28;01mNone\u001b[39;00m\n\u001b[0;32m     71\u001b[0m \u001b[38;5;28;01mfinally\u001b[39;00m:\n\u001b[0;32m     72\u001b[0m     \u001b[38;5;28;01mdel\u001b[39;00m filtered_tb\n",
      "File \u001b[1;32m~\\.conda\\envs\\tf_env\\lib\\site-packages\\tensorflow\\python\\eager\\execute.py:54\u001b[0m, in \u001b[0;36mquick_execute\u001b[1;34m(op_name, num_outputs, inputs, attrs, ctx, name)\u001b[0m\n\u001b[0;32m     52\u001b[0m \u001b[38;5;28;01mtry\u001b[39;00m:\n\u001b[0;32m     53\u001b[0m   ctx\u001b[38;5;241m.\u001b[39mensure_initialized()\n\u001b[1;32m---> 54\u001b[0m   tensors \u001b[38;5;241m=\u001b[39m pywrap_tfe\u001b[38;5;241m.\u001b[39mTFE_Py_Execute(ctx\u001b[38;5;241m.\u001b[39m_handle, device_name, op_name,\n\u001b[0;32m     55\u001b[0m                                       inputs, attrs, num_outputs)\n\u001b[0;32m     56\u001b[0m \u001b[38;5;28;01mexcept\u001b[39;00m core\u001b[38;5;241m.\u001b[39m_NotOkStatusException \u001b[38;5;28;01mas\u001b[39;00m e:\n\u001b[0;32m     57\u001b[0m   \u001b[38;5;28;01mif\u001b[39;00m name \u001b[38;5;129;01mis\u001b[39;00m \u001b[38;5;129;01mnot\u001b[39;00m \u001b[38;5;28;01mNone\u001b[39;00m:\n",
      "\u001b[1;31mInvalidArgumentError\u001b[0m: Graph execution error:\n\nDetected at node 'sequential_1/flatten_1/Reshape' defined at (most recent call last):\n    File \"C:\\Users\\saium\\.conda\\envs\\tf_env\\lib\\runpy.py\", line 194, in _run_module_as_main\n      return _run_code(code, main_globals, None,\n    File \"C:\\Users\\saium\\.conda\\envs\\tf_env\\lib\\runpy.py\", line 87, in _run_code\n      exec(code, run_globals)\n    File \"C:\\Users\\saium\\.conda\\envs\\tf_env\\lib\\site-packages\\ipykernel_launcher.py\", line 18, in <module>\n      app.launch_new_instance()\n    File \"C:\\Users\\saium\\.conda\\envs\\tf_env\\lib\\site-packages\\traitlets\\config\\application.py\", line 1075, in launch_instance\n      app.start()\n    File \"C:\\Users\\saium\\.conda\\envs\\tf_env\\lib\\site-packages\\ipykernel\\kernelapp.py\", line 739, in start\n      self.io_loop.start()\n    File \"C:\\Users\\saium\\.conda\\envs\\tf_env\\lib\\site-packages\\tornado\\platform\\asyncio.py\", line 205, in start\n      self.asyncio_loop.run_forever()\n    File \"C:\\Users\\saium\\.conda\\envs\\tf_env\\lib\\asyncio\\base_events.py\", line 570, in run_forever\n      self._run_once()\n    File \"C:\\Users\\saium\\.conda\\envs\\tf_env\\lib\\asyncio\\base_events.py\", line 1859, in _run_once\n      handle._run()\n    File \"C:\\Users\\saium\\.conda\\envs\\tf_env\\lib\\asyncio\\events.py\", line 81, in _run\n      self._context.run(self._callback, *self._args)\n    File \"C:\\Users\\saium\\.conda\\envs\\tf_env\\lib\\site-packages\\ipykernel\\kernelbase.py\", line 545, in dispatch_queue\n      await self.process_one()\n    File \"C:\\Users\\saium\\.conda\\envs\\tf_env\\lib\\site-packages\\ipykernel\\kernelbase.py\", line 534, in process_one\n      await dispatch(*args)\n    File \"C:\\Users\\saium\\.conda\\envs\\tf_env\\lib\\site-packages\\ipykernel\\kernelbase.py\", line 437, in dispatch_shell\n      await result\n    File \"C:\\Users\\saium\\.conda\\envs\\tf_env\\lib\\site-packages\\ipykernel\\ipkernel.py\", line 362, in execute_request\n      await super().execute_request(stream, ident, parent)\n    File \"C:\\Users\\saium\\.conda\\envs\\tf_env\\lib\\site-packages\\ipykernel\\kernelbase.py\", line 778, in execute_request\n      reply_content = await reply_content\n    File \"C:\\Users\\saium\\.conda\\envs\\tf_env\\lib\\site-packages\\ipykernel\\ipkernel.py\", line 449, in do_execute\n      res = shell.run_cell(\n    File \"C:\\Users\\saium\\.conda\\envs\\tf_env\\lib\\site-packages\\ipykernel\\zmqshell.py\", line 549, in run_cell\n      return super().run_cell(*args, **kwargs)\n    File \"C:\\Users\\saium\\.conda\\envs\\tf_env\\lib\\site-packages\\IPython\\core\\interactiveshell.py\", line 3009, in run_cell\n      result = self._run_cell(\n    File \"C:\\Users\\saium\\.conda\\envs\\tf_env\\lib\\site-packages\\IPython\\core\\interactiveshell.py\", line 3064, in _run_cell\n      result = runner(coro)\n    File \"C:\\Users\\saium\\.conda\\envs\\tf_env\\lib\\site-packages\\IPython\\core\\async_helpers.py\", line 129, in _pseudo_sync_runner\n      coro.send(None)\n    File \"C:\\Users\\saium\\.conda\\envs\\tf_env\\lib\\site-packages\\IPython\\core\\interactiveshell.py\", line 3269, in run_cell_async\n      has_raised = await self.run_ast_nodes(code_ast.body, cell_name,\n    File \"C:\\Users\\saium\\.conda\\envs\\tf_env\\lib\\site-packages\\IPython\\core\\interactiveshell.py\", line 3448, in run_ast_nodes\n      if await self.run_code(code, result, async_=asy):\n    File \"C:\\Users\\saium\\.conda\\envs\\tf_env\\lib\\site-packages\\IPython\\core\\interactiveshell.py\", line 3508, in run_code\n      exec(code_obj, self.user_global_ns, self.user_ns)\n    File \"C:\\Users\\saium\\AppData\\Local\\Temp\\ipykernel_70004\\3427472792.py\", line 1, in <module>\n      val_loss, val_acc = model.evaluate(val_generator)\n    File \"C:\\Users\\saium\\.conda\\envs\\tf_env\\lib\\site-packages\\keras\\utils\\traceback_utils.py\", line 65, in error_handler\n      return fn(*args, **kwargs)\n    File \"C:\\Users\\saium\\.conda\\envs\\tf_env\\lib\\site-packages\\keras\\engine\\training.py\", line 1947, in evaluate\n      tmp_logs = self.test_function(iterator)\n    File \"C:\\Users\\saium\\.conda\\envs\\tf_env\\lib\\site-packages\\keras\\engine\\training.py\", line 1727, in test_function\n      return step_function(self, iterator)\n    File \"C:\\Users\\saium\\.conda\\envs\\tf_env\\lib\\site-packages\\keras\\engine\\training.py\", line 1713, in step_function\n      outputs = model.distribute_strategy.run(run_step, args=(data,))\n    File \"C:\\Users\\saium\\.conda\\envs\\tf_env\\lib\\site-packages\\keras\\engine\\training.py\", line 1701, in run_step\n      outputs = model.test_step(data)\n    File \"C:\\Users\\saium\\.conda\\envs\\tf_env\\lib\\site-packages\\keras\\engine\\training.py\", line 1665, in test_step\n      y_pred = self(x, training=False)\n    File \"C:\\Users\\saium\\.conda\\envs\\tf_env\\lib\\site-packages\\keras\\utils\\traceback_utils.py\", line 65, in error_handler\n      return fn(*args, **kwargs)\n    File \"C:\\Users\\saium\\.conda\\envs\\tf_env\\lib\\site-packages\\keras\\engine\\training.py\", line 557, in __call__\n      return super().__call__(*args, **kwargs)\n    File \"C:\\Users\\saium\\.conda\\envs\\tf_env\\lib\\site-packages\\keras\\utils\\traceback_utils.py\", line 65, in error_handler\n      return fn(*args, **kwargs)\n    File \"C:\\Users\\saium\\.conda\\envs\\tf_env\\lib\\site-packages\\keras\\engine\\base_layer.py\", line 1097, in __call__\n      outputs = call_fn(inputs, *args, **kwargs)\n    File \"C:\\Users\\saium\\.conda\\envs\\tf_env\\lib\\site-packages\\keras\\utils\\traceback_utils.py\", line 96, in error_handler\n      return fn(*args, **kwargs)\n    File \"C:\\Users\\saium\\.conda\\envs\\tf_env\\lib\\site-packages\\keras\\engine\\sequential.py\", line 410, in call\n      return super().call(inputs, training=training, mask=mask)\n    File \"C:\\Users\\saium\\.conda\\envs\\tf_env\\lib\\site-packages\\keras\\engine\\functional.py\", line 510, in call\n      return self._run_internal_graph(inputs, training=training, mask=mask)\n    File \"C:\\Users\\saium\\.conda\\envs\\tf_env\\lib\\site-packages\\keras\\engine\\functional.py\", line 667, in _run_internal_graph\n      outputs = node.layer(*args, **kwargs)\n    File \"C:\\Users\\saium\\.conda\\envs\\tf_env\\lib\\site-packages\\keras\\utils\\traceback_utils.py\", line 65, in error_handler\n      return fn(*args, **kwargs)\n    File \"C:\\Users\\saium\\.conda\\envs\\tf_env\\lib\\site-packages\\keras\\engine\\base_layer.py\", line 1097, in __call__\n      outputs = call_fn(inputs, *args, **kwargs)\n    File \"C:\\Users\\saium\\.conda\\envs\\tf_env\\lib\\site-packages\\keras\\utils\\traceback_utils.py\", line 96, in error_handler\n      return fn(*args, **kwargs)\n    File \"C:\\Users\\saium\\.conda\\envs\\tf_env\\lib\\site-packages\\keras\\layers\\reshaping\\flatten.py\", line 104, in call\n      return tf.reshape(inputs, flattened_shape)\nNode: 'sequential_1/flatten_1/Reshape'\nInput to reshape is a tensor with 1843200 values, but the requested shape requires a multiple of 12544\n\t [[{{node sequential_1/flatten_1/Reshape}}]] [Op:__inference_test_function_486]"
     ]
    }
   ],
   "source": [
    "val_loss, val_acc = model.evaluate(val_generator)\n",
    "print(f\"Validation Accuracy: {val_acc*100:.2f}%\")\n"
   ]
  },
  {
   "cell_type": "code",
   "execution_count": 10,
   "id": "f1668828-3ed5-4907-8280-15a00ab49156",
   "metadata": {},
   "outputs": [
    {
     "ename": "SyntaxError",
     "evalue": "invalid syntax (26690703.py, line 3)",
     "output_type": "error",
     "traceback": [
      "\u001b[1;36m  Cell \u001b[1;32mIn[10], line 3\u001b[1;36m\u001b[0m\n\u001b[1;33m    target_size=(?, ?),   # <--- THIS is the size you must use\u001b[0m\n\u001b[1;37m                 ^\u001b[0m\n\u001b[1;31mSyntaxError\u001b[0m\u001b[1;31m:\u001b[0m invalid syntax\n"
     ]
    }
   ],
   "source": [
    "train_generator = train_datagen.flow_from_directory(\n",
    "    \"path/to/train\",\n",
    "    target_size=(?, ?),   # <--- THIS is the size you must use\n",
    "    ...\n",
    ")\n"
   ]
  },
  {
   "cell_type": "code",
   "execution_count": 11,
   "id": "a048fd27-dcf8-4844-8d21-2c440dabd8de",
   "metadata": {},
   "outputs": [
    {
     "ename": "SyntaxError",
     "evalue": "positional argument follows keyword argument (1887906703.py, line 4)",
     "output_type": "error",
     "traceback": [
      "\u001b[1;36m  Cell \u001b[1;32mIn[11], line 4\u001b[1;36m\u001b[0m\n\u001b[1;33m    ...\u001b[0m\n\u001b[1;37m    ^\u001b[0m\n\u001b[1;31mSyntaxError\u001b[0m\u001b[1;31m:\u001b[0m positional argument follows keyword argument\n"
     ]
    }
   ],
   "source": [
    "train_generator = train_datagen.flow_from_directory(\n",
    "    \"your_train_path\",\n",
    "    target_size=(...),  # <- THIS is the actual size you used\n",
    "    ...\n",
    ")\n"
   ]
  },
  {
   "cell_type": "code",
   "execution_count": 12,
   "id": "a8cf69e8-af84-4a26-8048-ccee2eabeb62",
   "metadata": {},
   "outputs": [
    {
     "name": "stdout",
     "output_type": "stream",
     "text": [
      "Found 15000 images belonging to 5 classes.\n"
     ]
    }
   ],
   "source": [
    "from tensorflow.keras.preprocessing.image import ImageDataGenerator\n",
    "\n",
    "val_datagen = ImageDataGenerator(rescale=1./255)\n",
    "\n",
    "val_generator = val_datagen.flow_from_directory(\n",
    "    \"../data/Rice_Image_Dataset_split/validation\",  # correct path\n",
    "    target_size=(224, 224),                         # match training\n",
    "    batch_size=32,\n",
    "    class_mode='categorical',\n",
    "    shuffle=False\n",
    ")\n"
   ]
  },
  {
   "cell_type": "code",
   "execution_count": 13,
   "id": "c8a7905e-750c-4b27-8b42-5a776f15033c",
   "metadata": {},
   "outputs": [
    {
     "ename": "InvalidArgumentError",
     "evalue": "Graph execution error:\n\nDetected at node 'sequential_1/flatten_1/Reshape' defined at (most recent call last):\n    File \"C:\\Users\\saium\\.conda\\envs\\tf_env\\lib\\runpy.py\", line 194, in _run_module_as_main\n      return _run_code(code, main_globals, None,\n    File \"C:\\Users\\saium\\.conda\\envs\\tf_env\\lib\\runpy.py\", line 87, in _run_code\n      exec(code, run_globals)\n    File \"C:\\Users\\saium\\.conda\\envs\\tf_env\\lib\\site-packages\\ipykernel_launcher.py\", line 18, in <module>\n      app.launch_new_instance()\n    File \"C:\\Users\\saium\\.conda\\envs\\tf_env\\lib\\site-packages\\traitlets\\config\\application.py\", line 1075, in launch_instance\n      app.start()\n    File \"C:\\Users\\saium\\.conda\\envs\\tf_env\\lib\\site-packages\\ipykernel\\kernelapp.py\", line 739, in start\n      self.io_loop.start()\n    File \"C:\\Users\\saium\\.conda\\envs\\tf_env\\lib\\site-packages\\tornado\\platform\\asyncio.py\", line 205, in start\n      self.asyncio_loop.run_forever()\n    File \"C:\\Users\\saium\\.conda\\envs\\tf_env\\lib\\asyncio\\base_events.py\", line 570, in run_forever\n      self._run_once()\n    File \"C:\\Users\\saium\\.conda\\envs\\tf_env\\lib\\asyncio\\base_events.py\", line 1859, in _run_once\n      handle._run()\n    File \"C:\\Users\\saium\\.conda\\envs\\tf_env\\lib\\asyncio\\events.py\", line 81, in _run\n      self._context.run(self._callback, *self._args)\n    File \"C:\\Users\\saium\\.conda\\envs\\tf_env\\lib\\site-packages\\ipykernel\\kernelbase.py\", line 545, in dispatch_queue\n      await self.process_one()\n    File \"C:\\Users\\saium\\.conda\\envs\\tf_env\\lib\\site-packages\\ipykernel\\kernelbase.py\", line 534, in process_one\n      await dispatch(*args)\n    File \"C:\\Users\\saium\\.conda\\envs\\tf_env\\lib\\site-packages\\ipykernel\\kernelbase.py\", line 437, in dispatch_shell\n      await result\n    File \"C:\\Users\\saium\\.conda\\envs\\tf_env\\lib\\site-packages\\ipykernel\\ipkernel.py\", line 362, in execute_request\n      await super().execute_request(stream, ident, parent)\n    File \"C:\\Users\\saium\\.conda\\envs\\tf_env\\lib\\site-packages\\ipykernel\\kernelbase.py\", line 778, in execute_request\n      reply_content = await reply_content\n    File \"C:\\Users\\saium\\.conda\\envs\\tf_env\\lib\\site-packages\\ipykernel\\ipkernel.py\", line 449, in do_execute\n      res = shell.run_cell(\n    File \"C:\\Users\\saium\\.conda\\envs\\tf_env\\lib\\site-packages\\ipykernel\\zmqshell.py\", line 549, in run_cell\n      return super().run_cell(*args, **kwargs)\n    File \"C:\\Users\\saium\\.conda\\envs\\tf_env\\lib\\site-packages\\IPython\\core\\interactiveshell.py\", line 3009, in run_cell\n      result = self._run_cell(\n    File \"C:\\Users\\saium\\.conda\\envs\\tf_env\\lib\\site-packages\\IPython\\core\\interactiveshell.py\", line 3064, in _run_cell\n      result = runner(coro)\n    File \"C:\\Users\\saium\\.conda\\envs\\tf_env\\lib\\site-packages\\IPython\\core\\async_helpers.py\", line 129, in _pseudo_sync_runner\n      coro.send(None)\n    File \"C:\\Users\\saium\\.conda\\envs\\tf_env\\lib\\site-packages\\IPython\\core\\interactiveshell.py\", line 3269, in run_cell_async\n      has_raised = await self.run_ast_nodes(code_ast.body, cell_name,\n    File \"C:\\Users\\saium\\.conda\\envs\\tf_env\\lib\\site-packages\\IPython\\core\\interactiveshell.py\", line 3448, in run_ast_nodes\n      if await self.run_code(code, result, async_=asy):\n    File \"C:\\Users\\saium\\.conda\\envs\\tf_env\\lib\\site-packages\\IPython\\core\\interactiveshell.py\", line 3508, in run_code\n      exec(code_obj, self.user_global_ns, self.user_ns)\n    File \"C:\\Users\\saium\\AppData\\Local\\Temp\\ipykernel_70004\\3427472792.py\", line 1, in <module>\n      val_loss, val_acc = model.evaluate(val_generator)\n    File \"C:\\Users\\saium\\.conda\\envs\\tf_env\\lib\\site-packages\\keras\\utils\\traceback_utils.py\", line 65, in error_handler\n      return fn(*args, **kwargs)\n    File \"C:\\Users\\saium\\.conda\\envs\\tf_env\\lib\\site-packages\\keras\\engine\\training.py\", line 1947, in evaluate\n      tmp_logs = self.test_function(iterator)\n    File \"C:\\Users\\saium\\.conda\\envs\\tf_env\\lib\\site-packages\\keras\\engine\\training.py\", line 1727, in test_function\n      return step_function(self, iterator)\n    File \"C:\\Users\\saium\\.conda\\envs\\tf_env\\lib\\site-packages\\keras\\engine\\training.py\", line 1713, in step_function\n      outputs = model.distribute_strategy.run(run_step, args=(data,))\n    File \"C:\\Users\\saium\\.conda\\envs\\tf_env\\lib\\site-packages\\keras\\engine\\training.py\", line 1701, in run_step\n      outputs = model.test_step(data)\n    File \"C:\\Users\\saium\\.conda\\envs\\tf_env\\lib\\site-packages\\keras\\engine\\training.py\", line 1665, in test_step\n      y_pred = self(x, training=False)\n    File \"C:\\Users\\saium\\.conda\\envs\\tf_env\\lib\\site-packages\\keras\\utils\\traceback_utils.py\", line 65, in error_handler\n      return fn(*args, **kwargs)\n    File \"C:\\Users\\saium\\.conda\\envs\\tf_env\\lib\\site-packages\\keras\\engine\\training.py\", line 557, in __call__\n      return super().__call__(*args, **kwargs)\n    File \"C:\\Users\\saium\\.conda\\envs\\tf_env\\lib\\site-packages\\keras\\utils\\traceback_utils.py\", line 65, in error_handler\n      return fn(*args, **kwargs)\n    File \"C:\\Users\\saium\\.conda\\envs\\tf_env\\lib\\site-packages\\keras\\engine\\base_layer.py\", line 1097, in __call__\n      outputs = call_fn(inputs, *args, **kwargs)\n    File \"C:\\Users\\saium\\.conda\\envs\\tf_env\\lib\\site-packages\\keras\\utils\\traceback_utils.py\", line 96, in error_handler\n      return fn(*args, **kwargs)\n    File \"C:\\Users\\saium\\.conda\\envs\\tf_env\\lib\\site-packages\\keras\\engine\\sequential.py\", line 410, in call\n      return super().call(inputs, training=training, mask=mask)\n    File \"C:\\Users\\saium\\.conda\\envs\\tf_env\\lib\\site-packages\\keras\\engine\\functional.py\", line 510, in call\n      return self._run_internal_graph(inputs, training=training, mask=mask)\n    File \"C:\\Users\\saium\\.conda\\envs\\tf_env\\lib\\site-packages\\keras\\engine\\functional.py\", line 667, in _run_internal_graph\n      outputs = node.layer(*args, **kwargs)\n    File \"C:\\Users\\saium\\.conda\\envs\\tf_env\\lib\\site-packages\\keras\\utils\\traceback_utils.py\", line 65, in error_handler\n      return fn(*args, **kwargs)\n    File \"C:\\Users\\saium\\.conda\\envs\\tf_env\\lib\\site-packages\\keras\\engine\\base_layer.py\", line 1097, in __call__\n      outputs = call_fn(inputs, *args, **kwargs)\n    File \"C:\\Users\\saium\\.conda\\envs\\tf_env\\lib\\site-packages\\keras\\utils\\traceback_utils.py\", line 96, in error_handler\n      return fn(*args, **kwargs)\n    File \"C:\\Users\\saium\\.conda\\envs\\tf_env\\lib\\site-packages\\keras\\layers\\reshaping\\flatten.py\", line 104, in call\n      return tf.reshape(inputs, flattened_shape)\nNode: 'sequential_1/flatten_1/Reshape'\nInput to reshape is a tensor with 5971968 values, but the requested shape requires a multiple of 12544\n\t [[{{node sequential_1/flatten_1/Reshape}}]] [Op:__inference_test_function_486]",
     "output_type": "error",
     "traceback": [
      "\u001b[1;31m---------------------------------------------------------------------------\u001b[0m",
      "\u001b[1;31mInvalidArgumentError\u001b[0m                      Traceback (most recent call last)",
      "Cell \u001b[1;32mIn[13], line 1\u001b[0m\n\u001b[1;32m----> 1\u001b[0m val_loss, val_acc \u001b[38;5;241m=\u001b[39m \u001b[43mmodel\u001b[49m\u001b[38;5;241;43m.\u001b[39;49m\u001b[43mevaluate\u001b[49m\u001b[43m(\u001b[49m\u001b[43mval_generator\u001b[49m\u001b[43m)\u001b[49m\n\u001b[0;32m      2\u001b[0m \u001b[38;5;28mprint\u001b[39m(\u001b[38;5;124mf\u001b[39m\u001b[38;5;124m\"\u001b[39m\u001b[38;5;124mValidation Accuracy: \u001b[39m\u001b[38;5;132;01m{\u001b[39;00mval_acc\u001b[38;5;241m*\u001b[39m\u001b[38;5;241m100\u001b[39m\u001b[38;5;132;01m:\u001b[39;00m\u001b[38;5;124m.2f\u001b[39m\u001b[38;5;132;01m}\u001b[39;00m\u001b[38;5;124m%\u001b[39m\u001b[38;5;124m\"\u001b[39m)\n\u001b[0;32m      3\u001b[0m \u001b[38;5;28mprint\u001b[39m(\u001b[38;5;124mf\u001b[39m\u001b[38;5;124m\"\u001b[39m\u001b[38;5;124mValidation Loss: \u001b[39m\u001b[38;5;132;01m{\u001b[39;00mval_loss\u001b[38;5;132;01m:\u001b[39;00m\u001b[38;5;124m.4f\u001b[39m\u001b[38;5;132;01m}\u001b[39;00m\u001b[38;5;124m\"\u001b[39m)\n",
      "File \u001b[1;32m~\\.conda\\envs\\tf_env\\lib\\site-packages\\keras\\utils\\traceback_utils.py:70\u001b[0m, in \u001b[0;36mfilter_traceback.<locals>.error_handler\u001b[1;34m(*args, **kwargs)\u001b[0m\n\u001b[0;32m     67\u001b[0m     filtered_tb \u001b[38;5;241m=\u001b[39m _process_traceback_frames(e\u001b[38;5;241m.\u001b[39m__traceback__)\n\u001b[0;32m     68\u001b[0m     \u001b[38;5;66;03m# To get the full stack trace, call:\u001b[39;00m\n\u001b[0;32m     69\u001b[0m     \u001b[38;5;66;03m# `tf.debugging.disable_traceback_filtering()`\u001b[39;00m\n\u001b[1;32m---> 70\u001b[0m     \u001b[38;5;28;01mraise\u001b[39;00m e\u001b[38;5;241m.\u001b[39mwith_traceback(filtered_tb) \u001b[38;5;28;01mfrom\u001b[39;00m \u001b[38;5;28;01mNone\u001b[39;00m\n\u001b[0;32m     71\u001b[0m \u001b[38;5;28;01mfinally\u001b[39;00m:\n\u001b[0;32m     72\u001b[0m     \u001b[38;5;28;01mdel\u001b[39;00m filtered_tb\n",
      "File \u001b[1;32m~\\.conda\\envs\\tf_env\\lib\\site-packages\\tensorflow\\python\\eager\\execute.py:54\u001b[0m, in \u001b[0;36mquick_execute\u001b[1;34m(op_name, num_outputs, inputs, attrs, ctx, name)\u001b[0m\n\u001b[0;32m     52\u001b[0m \u001b[38;5;28;01mtry\u001b[39;00m:\n\u001b[0;32m     53\u001b[0m   ctx\u001b[38;5;241m.\u001b[39mensure_initialized()\n\u001b[1;32m---> 54\u001b[0m   tensors \u001b[38;5;241m=\u001b[39m pywrap_tfe\u001b[38;5;241m.\u001b[39mTFE_Py_Execute(ctx\u001b[38;5;241m.\u001b[39m_handle, device_name, op_name,\n\u001b[0;32m     55\u001b[0m                                       inputs, attrs, num_outputs)\n\u001b[0;32m     56\u001b[0m \u001b[38;5;28;01mexcept\u001b[39;00m core\u001b[38;5;241m.\u001b[39m_NotOkStatusException \u001b[38;5;28;01mas\u001b[39;00m e:\n\u001b[0;32m     57\u001b[0m   \u001b[38;5;28;01mif\u001b[39;00m name \u001b[38;5;129;01mis\u001b[39;00m \u001b[38;5;129;01mnot\u001b[39;00m \u001b[38;5;28;01mNone\u001b[39;00m:\n",
      "\u001b[1;31mInvalidArgumentError\u001b[0m: Graph execution error:\n\nDetected at node 'sequential_1/flatten_1/Reshape' defined at (most recent call last):\n    File \"C:\\Users\\saium\\.conda\\envs\\tf_env\\lib\\runpy.py\", line 194, in _run_module_as_main\n      return _run_code(code, main_globals, None,\n    File \"C:\\Users\\saium\\.conda\\envs\\tf_env\\lib\\runpy.py\", line 87, in _run_code\n      exec(code, run_globals)\n    File \"C:\\Users\\saium\\.conda\\envs\\tf_env\\lib\\site-packages\\ipykernel_launcher.py\", line 18, in <module>\n      app.launch_new_instance()\n    File \"C:\\Users\\saium\\.conda\\envs\\tf_env\\lib\\site-packages\\traitlets\\config\\application.py\", line 1075, in launch_instance\n      app.start()\n    File \"C:\\Users\\saium\\.conda\\envs\\tf_env\\lib\\site-packages\\ipykernel\\kernelapp.py\", line 739, in start\n      self.io_loop.start()\n    File \"C:\\Users\\saium\\.conda\\envs\\tf_env\\lib\\site-packages\\tornado\\platform\\asyncio.py\", line 205, in start\n      self.asyncio_loop.run_forever()\n    File \"C:\\Users\\saium\\.conda\\envs\\tf_env\\lib\\asyncio\\base_events.py\", line 570, in run_forever\n      self._run_once()\n    File \"C:\\Users\\saium\\.conda\\envs\\tf_env\\lib\\asyncio\\base_events.py\", line 1859, in _run_once\n      handle._run()\n    File \"C:\\Users\\saium\\.conda\\envs\\tf_env\\lib\\asyncio\\events.py\", line 81, in _run\n      self._context.run(self._callback, *self._args)\n    File \"C:\\Users\\saium\\.conda\\envs\\tf_env\\lib\\site-packages\\ipykernel\\kernelbase.py\", line 545, in dispatch_queue\n      await self.process_one()\n    File \"C:\\Users\\saium\\.conda\\envs\\tf_env\\lib\\site-packages\\ipykernel\\kernelbase.py\", line 534, in process_one\n      await dispatch(*args)\n    File \"C:\\Users\\saium\\.conda\\envs\\tf_env\\lib\\site-packages\\ipykernel\\kernelbase.py\", line 437, in dispatch_shell\n      await result\n    File \"C:\\Users\\saium\\.conda\\envs\\tf_env\\lib\\site-packages\\ipykernel\\ipkernel.py\", line 362, in execute_request\n      await super().execute_request(stream, ident, parent)\n    File \"C:\\Users\\saium\\.conda\\envs\\tf_env\\lib\\site-packages\\ipykernel\\kernelbase.py\", line 778, in execute_request\n      reply_content = await reply_content\n    File \"C:\\Users\\saium\\.conda\\envs\\tf_env\\lib\\site-packages\\ipykernel\\ipkernel.py\", line 449, in do_execute\n      res = shell.run_cell(\n    File \"C:\\Users\\saium\\.conda\\envs\\tf_env\\lib\\site-packages\\ipykernel\\zmqshell.py\", line 549, in run_cell\n      return super().run_cell(*args, **kwargs)\n    File \"C:\\Users\\saium\\.conda\\envs\\tf_env\\lib\\site-packages\\IPython\\core\\interactiveshell.py\", line 3009, in run_cell\n      result = self._run_cell(\n    File \"C:\\Users\\saium\\.conda\\envs\\tf_env\\lib\\site-packages\\IPython\\core\\interactiveshell.py\", line 3064, in _run_cell\n      result = runner(coro)\n    File \"C:\\Users\\saium\\.conda\\envs\\tf_env\\lib\\site-packages\\IPython\\core\\async_helpers.py\", line 129, in _pseudo_sync_runner\n      coro.send(None)\n    File \"C:\\Users\\saium\\.conda\\envs\\tf_env\\lib\\site-packages\\IPython\\core\\interactiveshell.py\", line 3269, in run_cell_async\n      has_raised = await self.run_ast_nodes(code_ast.body, cell_name,\n    File \"C:\\Users\\saium\\.conda\\envs\\tf_env\\lib\\site-packages\\IPython\\core\\interactiveshell.py\", line 3448, in run_ast_nodes\n      if await self.run_code(code, result, async_=asy):\n    File \"C:\\Users\\saium\\.conda\\envs\\tf_env\\lib\\site-packages\\IPython\\core\\interactiveshell.py\", line 3508, in run_code\n      exec(code_obj, self.user_global_ns, self.user_ns)\n    File \"C:\\Users\\saium\\AppData\\Local\\Temp\\ipykernel_70004\\3427472792.py\", line 1, in <module>\n      val_loss, val_acc = model.evaluate(val_generator)\n    File \"C:\\Users\\saium\\.conda\\envs\\tf_env\\lib\\site-packages\\keras\\utils\\traceback_utils.py\", line 65, in error_handler\n      return fn(*args, **kwargs)\n    File \"C:\\Users\\saium\\.conda\\envs\\tf_env\\lib\\site-packages\\keras\\engine\\training.py\", line 1947, in evaluate\n      tmp_logs = self.test_function(iterator)\n    File \"C:\\Users\\saium\\.conda\\envs\\tf_env\\lib\\site-packages\\keras\\engine\\training.py\", line 1727, in test_function\n      return step_function(self, iterator)\n    File \"C:\\Users\\saium\\.conda\\envs\\tf_env\\lib\\site-packages\\keras\\engine\\training.py\", line 1713, in step_function\n      outputs = model.distribute_strategy.run(run_step, args=(data,))\n    File \"C:\\Users\\saium\\.conda\\envs\\tf_env\\lib\\site-packages\\keras\\engine\\training.py\", line 1701, in run_step\n      outputs = model.test_step(data)\n    File \"C:\\Users\\saium\\.conda\\envs\\tf_env\\lib\\site-packages\\keras\\engine\\training.py\", line 1665, in test_step\n      y_pred = self(x, training=False)\n    File \"C:\\Users\\saium\\.conda\\envs\\tf_env\\lib\\site-packages\\keras\\utils\\traceback_utils.py\", line 65, in error_handler\n      return fn(*args, **kwargs)\n    File \"C:\\Users\\saium\\.conda\\envs\\tf_env\\lib\\site-packages\\keras\\engine\\training.py\", line 557, in __call__\n      return super().__call__(*args, **kwargs)\n    File \"C:\\Users\\saium\\.conda\\envs\\tf_env\\lib\\site-packages\\keras\\utils\\traceback_utils.py\", line 65, in error_handler\n      return fn(*args, **kwargs)\n    File \"C:\\Users\\saium\\.conda\\envs\\tf_env\\lib\\site-packages\\keras\\engine\\base_layer.py\", line 1097, in __call__\n      outputs = call_fn(inputs, *args, **kwargs)\n    File \"C:\\Users\\saium\\.conda\\envs\\tf_env\\lib\\site-packages\\keras\\utils\\traceback_utils.py\", line 96, in error_handler\n      return fn(*args, **kwargs)\n    File \"C:\\Users\\saium\\.conda\\envs\\tf_env\\lib\\site-packages\\keras\\engine\\sequential.py\", line 410, in call\n      return super().call(inputs, training=training, mask=mask)\n    File \"C:\\Users\\saium\\.conda\\envs\\tf_env\\lib\\site-packages\\keras\\engine\\functional.py\", line 510, in call\n      return self._run_internal_graph(inputs, training=training, mask=mask)\n    File \"C:\\Users\\saium\\.conda\\envs\\tf_env\\lib\\site-packages\\keras\\engine\\functional.py\", line 667, in _run_internal_graph\n      outputs = node.layer(*args, **kwargs)\n    File \"C:\\Users\\saium\\.conda\\envs\\tf_env\\lib\\site-packages\\keras\\utils\\traceback_utils.py\", line 65, in error_handler\n      return fn(*args, **kwargs)\n    File \"C:\\Users\\saium\\.conda\\envs\\tf_env\\lib\\site-packages\\keras\\engine\\base_layer.py\", line 1097, in __call__\n      outputs = call_fn(inputs, *args, **kwargs)\n    File \"C:\\Users\\saium\\.conda\\envs\\tf_env\\lib\\site-packages\\keras\\utils\\traceback_utils.py\", line 96, in error_handler\n      return fn(*args, **kwargs)\n    File \"C:\\Users\\saium\\.conda\\envs\\tf_env\\lib\\site-packages\\keras\\layers\\reshaping\\flatten.py\", line 104, in call\n      return tf.reshape(inputs, flattened_shape)\nNode: 'sequential_1/flatten_1/Reshape'\nInput to reshape is a tensor with 5971968 values, but the requested shape requires a multiple of 12544\n\t [[{{node sequential_1/flatten_1/Reshape}}]] [Op:__inference_test_function_486]"
     ]
    }
   ],
   "source": [
    "val_loss, val_acc = model.evaluate(val_generator)\n",
    "print(f\"Validation Accuracy: {val_acc*100:.2f}%\")\n",
    "print(f\"Validation Loss: {val_loss:.4f}\")\n"
   ]
  },
  {
   "cell_type": "code",
   "execution_count": 14,
   "id": "99b71394-d62c-4bb9-a565-41658727f6d5",
   "metadata": {},
   "outputs": [
    {
     "name": "stdout",
     "output_type": "stream",
     "text": [
      "Model Input Shape: (None, 64, 64, 3)\n"
     ]
    }
   ],
   "source": [
    "print(\"Model Input Shape:\", model.input_shape)\n"
   ]
  },
  {
   "cell_type": "code",
   "execution_count": 15,
   "id": "f3efedda-3b33-4af1-88b6-a6321ca362e0",
   "metadata": {},
   "outputs": [
    {
     "name": "stdout",
     "output_type": "stream",
     "text": [
      "Found 15000 images belonging to 5 classes.\n"
     ]
    }
   ],
   "source": [
    "val_generator = val_datagen.flow_from_directory(\n",
    "    \"../data/Rice_Image_Dataset_split/validation\",\n",
    "    target_size=(64, 64),  # ✅ match model's input size\n",
    "    batch_size=32,\n",
    "    class_mode='categorical',\n",
    "    shuffle=False\n",
    ")\n"
   ]
  },
  {
   "cell_type": "code",
   "execution_count": 16,
   "id": "2e8c5798-68aa-4988-bff2-3e53ba256409",
   "metadata": {},
   "outputs": [
    {
     "name": "stdout",
     "output_type": "stream",
     "text": [
      "469/469 [==============================] - 65s 139ms/step - loss: 0.1049 - accuracy: 0.9629\n",
      "Validation Accuracy: 96.29%\n",
      "Validation Loss: 0.1049\n"
     ]
    }
   ],
   "source": [
    "val_loss, val_acc = model.evaluate(val_generator)\n",
    "print(f\"Validation Accuracy: {val_acc*100:.2f}%\")\n",
    "print(f\"Validation Loss: {val_loss:.4f}\")\n"
   ]
  },
  {
   "cell_type": "code",
   "execution_count": null,
   "id": "c94e9c24-40d7-45b4-a3bd-a7fd191f185b",
   "metadata": {},
   "outputs": [],
   "source": []
  }
 ],
 "metadata": {
  "kernelspec": {
   "display_name": "Python [conda env:.conda-tf_env]",
   "language": "python",
   "name": "conda-env-.conda-tf_env-py"
  },
  "language_info": {
   "codemirror_mode": {
    "name": "ipython",
    "version": 3
   },
   "file_extension": ".py",
   "mimetype": "text/x-python",
   "name": "python",
   "nbconvert_exporter": "python",
   "pygments_lexer": "ipython3",
   "version": "3.8.20"
  }
 },
 "nbformat": 4,
 "nbformat_minor": 5
}
